package idim.dims.testdim.structures;

import idim.blocks.Blocks;
import idim.dims.testdim.worldgen.LDTreasure;
import idim.treasure.Treasures;

import java.util.Random;

import net.minecraft.block.Block;
import net.minecraft.tileentity.TileEntityMobSpawner;
import net.minecraft.world.World;
import net.minecraft.world.gen.feature.WorldGenerator;
import net.minecraftforge.common.DungeonHooks;

public class WorldGenCrystalTower extends WorldGenerator
{
	int randInt = (int) (Math.random() * Math.floor(10));
	int randBlockInt = (int) (Math.random() * Math.floor(4));
	int selectedBlock = (randBlockInt <= 2) ? Blocks.desertCrystal.blockID
			: Blocks.lostCrystal.blockID;
	
	public WorldGenCrystalTower() {
	}
	
	protected int[] GetValidSpawnBlocks() {
		return new int[] { Blocks.purpleSand.blockID };
	}
	
	public boolean LocationIsValidSpawn(World world, int i, int j, int k) {
		int distanceToAir = 0;
		int checkID = world.getBlockId(i, j, k);
		
		while (checkID != 0) {
			distanceToAir++;
			checkID = world.getBlockId(i, j + distanceToAir, k);
		}
		
		if (distanceToAir > 3) {
			return false;
		}
		j += distanceToAir - 1;
		
		int blockID = world.getBlockId(i, j, k);
		int blockIDAbove = world.getBlockId(i, j + 1, k);
		int blockIDBelow = world.getBlockId(i, j - 1, k);
		for (int x : GetValidSpawnBlocks()) {
			if (blockIDAbove != 0) {
				return false;
			}
			if (blockID == x) {
				return true;
			} else if (blockID == Blocks.purpleCaveStone.blockID
					&& blockIDBelow == x) {
				return true;
			}
		}
		return false;
	}
	
	@Override
	public boolean generate(World world, Random rand, int i, int j, int k) {
		// check that each corner is one of the valid spawn blocks
		if (!LocationIsValidSpawn(world, i, j, k)) {
			return false;
		}
		selectedBlock = (randBlockInt <= 2) ? Blocks.desertCrystal.blockID
				: Blocks.lostCrystal.blockID;
		world.setBlock(i + 4, j + 2, k + 10, selectedBlock);
		world.setBlock(i + 4, j + 2, k + 11, selectedBlock);
		world.setBlock(i + 4, j + 2, k + 12, selectedBlock);
		world.setBlock(i + 4, j + 2, k + 13, selectedBlock);
		world.setBlock(i + 4, j + 2, k + 14, selectedBlock);
		world.setBlock(i + 4, j + 2, k + 15, selectedBlock);
		world.setBlock(i + 4, j + 2, k + 16, selectedBlock);
		world.setBlock(i + 4, j + 3, k + 10, selectedBlock);
		world.setBlock(i + 4, j + 3, k + 11, selectedBlock);
		world.setBlock(i + 4, j + 3, k + 12, selectedBlock);
		world.setBlock(i + 4, j + 3, k + 13, selectedBlock);
		world.setBlock(i + 4, j + 3, k + 14, selectedBlock);
		world.setBlock(i + 4, j + 3, k + 15, selectedBlock);
		world.setBlock(i + 4, j + 3, k + 16, selectedBlock);
		world.setBlock(i + 4, j + 4, k + 10, selectedBlock);
		world.setBlock(i + 4, j + 4, k + 11, selectedBlock);
		world.setBlock(i + 4, j + 4, k + 12, selectedBlock);
		world.setBlock(i + 4, j + 4, k + 13, selectedBlock);
		world.setBlock(i + 4, j + 4, k + 14, selectedBlock);
		world.setBlock(i + 4, j + 4, k + 15, selectedBlock);
		world.setBlock(i + 4, j + 4, k + 16, selectedBlock);
		world.setBlock(i + 4, j + 5, k + 10, selectedBlock);
		world.setBlock(i + 4, j + 5, k + 11, selectedBlock);
		world.setBlock(i + 4, j + 5, k + 12, selectedBlock);
		world.setBlock(i + 4, j + 5, k + 13, selectedBlock);
		world.setBlock(i + 4, j + 5, k + 14, selectedBlock);
		world.setBlock(i + 4, j + 5, k + 15, selectedBlock);
		world.setBlock(i + 4, j + 5, k + 16, selectedBlock);
		world.setBlock(i + 4, j + 6, k + 10, selectedBlock);
		world.setBlock(i + 4, j + 6, k + 11, selectedBlock);
		world.setBlock(i + 4, j + 6, k + 12, selectedBlock);
		world.setBlock(i + 4, j + 6, k + 13, selectedBlock);
		world.setBlock(i + 4, j + 6, k + 14, selectedBlock);
		world.setBlock(i + 4, j + 6, k + 15, selectedBlock);
		world.setBlock(i + 4, j + 6, k + 16, selectedBlock);
		world.setBlock(i + 4, j + 7, k + 10, selectedBlock);
		world.setBlock(i + 4, j + 7, k + 11, selectedBlock);
		world.setBlock(i + 4, j + 7, k + 12, selectedBlock);
		world.setBlock(i + 4, j + 7, k + 13, selectedBlock);
		world.setBlock(i + 4, j + 7, k + 14, selectedBlock);
		world.setBlock(i + 4, j + 7, k + 15, selectedBlock);
		world.setBlock(i + 4, j + 7, k + 16, selectedBlock);
		world.setBlock(i + 4, j + 8, k + 10, selectedBlock);
		world.setBlock(i + 4, j + 8, k + 11, selectedBlock);
		world.setBlock(i + 4, j + 8, k + 12, selectedBlock);
		world.setBlock(i + 4, j + 8, k + 13, selectedBlock);
		world.setBlock(i + 4, j + 8, k + 14, selectedBlock);
		world.setBlock(i + 4, j + 8, k + 15, selectedBlock);
		world.setBlock(i + 4, j + 8, k + 16, selectedBlock);
		if (randInt <= 6) {
			int chestX = i + 5;
			int chestY = j + 0;
			int chestZ = k + 13;
			int chestRand = (int) (Math.random() * Math.floor(2));
			boolean isBigChest = (chestRand == 1) ? true : false;
			String chestString = chestX + " " + chestY + " " + chestZ;
			LDTreasure.addChest(world, rand, chestX, chestY, chestZ,
					isBigChest,
					Treasures.pickChestType());
		}
		world.setBlock(i + 5, j + 2, k + 8, selectedBlock);
		world.setBlock(i + 5, j + 2, k + 9, selectedBlock);
		world.setBlock(i + 5, j + 2, k + 17, selectedBlock);
		world.setBlock(i + 5, j + 2, k + 18, selectedBlock);
		world.setBlock(i + 5, j + 3, k + 8, selectedBlock);
		world.setBlock(i + 5, j + 3, k + 9, selectedBlock);
		world.setBlock(i + 5, j + 3, k + 17, selectedBlock);
		world.setBlock(i + 5, j + 3, k + 18, selectedBlock);
		world.setBlock(i + 5, j + 4, k + 8, selectedBlock);
		world.setBlock(i + 5, j + 4, k + 9, selectedBlock);
		world.setBlock(i + 5, j + 4, k + 17, selectedBlock);
		world.setBlock(i + 5, j + 4, k + 18, selectedBlock);
		world.setBlock(i + 5, j + 5, k + 8, selectedBlock);
		world.setBlock(i + 5, j + 5, k + 9, selectedBlock);
		world.setBlock(i + 5, j + 5, k + 17, selectedBlock);
		world.setBlock(i + 5, j + 5, k + 18, selectedBlock);
		world.setBlock(i + 5, j + 6, k + 8, selectedBlock);
		world.setBlock(i + 5, j + 6, k + 9, selectedBlock);
		world.setBlock(i + 5, j + 6, k + 17, selectedBlock);
		world.setBlock(i + 5, j + 6, k + 18, selectedBlock);
		world.setBlock(i + 5, j + 7, k + 8, selectedBlock);
		world.setBlock(i + 5, j + 7, k + 9, selectedBlock);
		world.setBlock(i + 5, j + 7, k + 17, selectedBlock);
		world.setBlock(i + 5, j + 7, k + 18, selectedBlock);
		world.setBlock(i + 5, j + 8, k + 8, selectedBlock);
		world.setBlock(i + 5, j + 8, k + 9, selectedBlock);
		world.setBlock(i + 5, j + 8, k + 10, selectedBlock);
		world.setBlock(i + 5, j + 8, k + 11, selectedBlock);
		world.setBlock(i + 5, j + 8, k + 12, selectedBlock);
		world.setBlock(i + 5, j + 8, k + 13, selectedBlock);
		world.setBlock(i + 5, j + 8, k + 14, selectedBlock);
		world.setBlock(i + 5, j + 8, k + 15, selectedBlock);
		world.setBlock(i + 5, j + 8, k + 16, selectedBlock);
		world.setBlock(i + 5, j + 8, k + 17, selectedBlock);
		world.setBlock(i + 5, j + 8, k + 18, selectedBlock);
		world.setBlock(i + 5, j + 9, k + 10, selectedBlock);
		world.setBlock(i + 5, j + 9, k + 11, selectedBlock);
		world.setBlock(i + 5, j + 9, k + 12, selectedBlock);
		world.setBlock(i + 5, j + 9, k + 13, selectedBlock);
		world.setBlock(i + 5, j + 9, k + 14, selectedBlock);
		world.setBlock(i + 5, j + 9, k + 15, selectedBlock);
		world.setBlock(i + 5, j + 9, k + 16, selectedBlock);
		
		world.setBlock(i + 6, j + 2, k + 7, selectedBlock);
		world.setBlock(i + 6, j + 2, k + 19, selectedBlock);
		world.setBlock(i + 6, j + 3, k + 7, selectedBlock);
		world.setBlock(i + 6, j + 3, k + 19, selectedBlock);
		world.setBlock(i + 6, j + 4, k + 7, selectedBlock);
		world.setBlock(i + 6, j + 4, k + 19, selectedBlock);
		world.setBlock(i + 6, j + 5, k + 7, selectedBlock);
		world.setBlock(i + 6, j + 5, k + 19, selectedBlock);
		world.setBlock(i + 6, j + 6, k + 7, selectedBlock);
		world.setBlock(i + 6, j + 6, k + 19, selectedBlock);
		world.setBlock(i + 6, j + 7, k + 7, selectedBlock);
		world.setBlock(i + 6, j + 7, k + 19, selectedBlock);
		world.setBlock(i + 6, j + 8, k + 7, selectedBlock);
		world.setBlock(i + 6, j + 8, k + 8, selectedBlock);
		world.setBlock(i + 6, j + 8, k + 9, selectedBlock);
		world.setBlock(i + 6, j + 8, k + 17, selectedBlock);
		world.setBlock(i + 6, j + 8, k + 18, selectedBlock);
		world.setBlock(i + 6, j + 8, k + 19, selectedBlock);
		world.setBlock(i + 6, j + 9, k + 8, selectedBlock);
		world.setBlock(i + 6, j + 9, k + 9, selectedBlock);
		world.setBlock(i + 6, j + 9, k + 10, selectedBlock);
		world.setBlock(i + 6, j + 9, k + 16, selectedBlock);
		world.setBlock(i + 6, j + 9, k + 17, selectedBlock);
		world.setBlock(i + 6, j + 9, k + 18, selectedBlock);
		world.setBlock(i + 6, j + 10, k + 11, selectedBlock);
		world.setBlock(i + 6, j + 10, k + 12, selectedBlock);
		world.setBlock(i + 6, j + 10, k + 13, selectedBlock);
		world.setBlock(i + 6, j + 10, k + 14, selectedBlock);
		world.setBlock(i + 6, j + 10, k + 15, selectedBlock);
		world.setBlock(i + 6, j + 11, k + 11, selectedBlock);
		world.setBlock(i + 6, j + 11, k + 12, selectedBlock);
		world.setBlock(i + 6, j + 11, k + 13, selectedBlock);
		world.setBlock(i + 6, j + 11, k + 14, selectedBlock);
		world.setBlock(i + 6, j + 11, k + 15, selectedBlock);
		world.setBlock(i + 7, j + 2, k + 6, selectedBlock);
		world.setBlock(i + 7, j + 2, k + 20, selectedBlock);
		world.setBlock(i + 7, j + 3, k + 6, selectedBlock);
		world.setBlock(i + 7, j + 3, k + 20, selectedBlock);
		world.setBlock(i + 7, j + 4, k + 6, selectedBlock);
		world.setBlock(i + 7, j + 4, k + 20, selectedBlock);
		world.setBlock(i + 7, j + 5, k + 6, selectedBlock);
		world.setBlock(i + 7, j + 5, k + 20, selectedBlock);
		world.setBlock(i + 7, j + 6, k + 6, selectedBlock);
		world.setBlock(i + 7, j + 6, k + 20, selectedBlock);
		world.setBlock(i + 7, j + 7, k + 6, selectedBlock);
		world.setBlock(i + 7, j + 7, k + 20, selectedBlock);
		world.setBlock(i + 7, j + 8, k + 6, selectedBlock);
		world.setBlock(i + 7, j + 8, k + 7, selectedBlock);
		world.setBlock(i + 7, j + 8, k + 19, selectedBlock);
		world.setBlock(i + 7, j + 8, k + 20, selectedBlock);
		world.setBlock(i + 7, j + 9, k + 7, selectedBlock);
		world.setBlock(i + 7, j + 9, k + 8, selectedBlock);
		world.setBlock(i + 7, j + 9, k + 18, selectedBlock);
		world.setBlock(i + 7, j + 9, k + 19, selectedBlock);
		world.setBlock(i + 7, j + 10, k + 9, selectedBlock);
		world.setBlock(i + 7, j + 10, k + 10, selectedBlock);
		world.setBlock(i + 7, j + 10, k + 16, selectedBlock);
		world.setBlock(i + 7, j + 10, k + 17, selectedBlock);
		world.setBlock(i + 7, j + 11, k + 9, selectedBlock);
		world.setBlock(i + 7, j + 11, k + 10, selectedBlock);
		world.setBlock(i + 7, j + 11, k + 16, selectedBlock);
		world.setBlock(i + 7, j + 11, k + 17, selectedBlock);
		world.setBlock(i + 7, j + 12, k + 11, selectedBlock);
		world.setBlock(i + 7, j + 12, k + 12, selectedBlock);
		world.setBlock(i + 7, j + 12, k + 13, selectedBlock);
		world.setBlock(i + 7, j + 12, k + 14, selectedBlock);
		world.setBlock(i + 7, j + 12, k + 15, selectedBlock);
		world.setBlock(i + 7, j + 13, k + 11, selectedBlock);
		world.setBlock(i + 7, j + 13, k + 12, selectedBlock);
		world.setBlock(i + 7, j + 13, k + 13, selectedBlock);
		world.setBlock(i + 7, j + 13, k + 14, selectedBlock);
		world.setBlock(i + 7, j + 13, k + 15, selectedBlock);
		world.setBlock(i + 8, j + 2, k + 5, selectedBlock);
		world.setBlock(i + 8, j + 2, k + 21, selectedBlock);
		world.setBlock(i + 8, j + 3, k + 5, selectedBlock);
		world.setBlock(i + 8, j + 3, k + 21, selectedBlock);
		world.setBlock(i + 8, j + 4, k + 5, selectedBlock);
		world.setBlock(i + 8, j + 4, k + 21, selectedBlock);
		world.setBlock(i + 8, j + 5, k + 5, selectedBlock);
		world.setBlock(i + 8, j + 5, k + 21, selectedBlock);
		world.setBlock(i + 8, j + 6, k + 5, selectedBlock);
		world.setBlock(i + 8, j + 6, k + 21, selectedBlock);
		world.setBlock(i + 8, j + 7, k + 5, selectedBlock);
		world.setBlock(i + 8, j + 7, k + 21, selectedBlock);
		world.setBlock(i + 8, j + 8, k + 5, selectedBlock);
		world.setBlock(i + 8, j + 8, k + 6, selectedBlock);
		world.setBlock(i + 8, j + 8, k + 20, selectedBlock);
		world.setBlock(i + 8, j + 8, k + 21, selectedBlock);
		world.setBlock(i + 8, j + 9, k + 6, selectedBlock);
		world.setBlock(i + 8, j + 9, k + 20, selectedBlock);
		world.setBlock(i + 8, j + 10, k + 7, selectedBlock);
		world.setBlock(i + 8, j + 10, k + 8, selectedBlock);
		world.setBlock(i + 8, j + 10, k + 18, selectedBlock);
		world.setBlock(i + 8, j + 10, k + 19, selectedBlock);
		world.setBlock(i + 8, j + 11, k + 7, selectedBlock);
		world.setBlock(i + 8, j + 11, k + 8, selectedBlock);
		world.setBlock(i + 8, j + 11, k + 18, selectedBlock);
		world.setBlock(i + 8, j + 11, k + 19, selectedBlock);
		world.setBlock(i + 8, j + 12, k + 9, selectedBlock);
		world.setBlock(i + 8, j + 12, k + 10, selectedBlock);
		world.setBlock(i + 8, j + 12, k + 16, selectedBlock);
		world.setBlock(i + 8, j + 12, k + 17, selectedBlock);
		world.setBlock(i + 8, j + 13, k + 9, selectedBlock);
		world.setBlock(i + 8, j + 13, k + 10, selectedBlock);
		world.setBlock(i + 8, j + 13, k + 16, selectedBlock);
		world.setBlock(i + 8, j + 13, k + 17, selectedBlock);
		world.setBlock(i + 8, j + 14, k + 11, selectedBlock);
		world.setBlock(i + 8, j + 14, k + 12, selectedBlock);
		world.setBlock(i + 8, j + 14, k + 13, selectedBlock);
		world.setBlock(i + 8, j + 14, k + 14, selectedBlock);
		world.setBlock(i + 8, j + 14, k + 15, selectedBlock);
		world.setBlock(i + 8, j + 15, k + 11, selectedBlock);
		world.setBlock(i + 8, j + 15, k + 12, selectedBlock);
		world.setBlock(i + 8, j + 15, k + 13, selectedBlock);
		world.setBlock(i + 8, j + 15, k + 14, selectedBlock);
		world.setBlock(i + 8, j + 15, k + 15, selectedBlock);
		world.setBlock(i + 9, j + 2, k + 4, selectedBlock);
		world.setBlock(i + 9, j + 2, k + 22, selectedBlock);
		world.setBlock(i + 9, j + 3, k + 4, selectedBlock);
		world.setBlock(i + 9, j + 3, k + 22, selectedBlock);
		world.setBlock(i + 9, j + 4, k + 4, selectedBlock);
		world.setBlock(i + 9, j + 4, k + 22, selectedBlock);
		world.setBlock(i + 9, j + 5, k + 4, selectedBlock);
		world.setBlock(i + 9, j + 5, k + 22, selectedBlock);
		world.setBlock(i + 9, j + 6, k + 4, selectedBlock);
		world.setBlock(i + 9, j + 6, k + 22, selectedBlock);
		world.setBlock(i + 9, j + 7, k + 4, selectedBlock);
		world.setBlock(i + 9, j + 7, k + 22, selectedBlock);
		world.setBlock(i + 9, j + 8, k + 4, selectedBlock);
		world.setBlock(i + 9, j + 8, k + 5, selectedBlock);
		world.setBlock(i + 9, j + 8, k + 21, selectedBlock);
		world.setBlock(i + 9, j + 8, k + 22, selectedBlock);
		world.setBlock(i + 9, j + 9, k + 5, selectedBlock);
		world.setBlock(i + 9, j + 9, k + 6, selectedBlock);
		world.setBlock(i + 9, j + 9, k + 20, selectedBlock);
		world.setBlock(i + 9, j + 9, k + 21, selectedBlock);
		world.setBlock(i + 9, j + 10, k + 7, selectedBlock);
		world.setBlock(i + 9, j + 10, k + 19, selectedBlock);
		world.setBlock(i + 9, j + 11, k + 7, selectedBlock);
		world.setBlock(i + 9, j + 11, k + 19, selectedBlock);
		world.setBlock(i + 9, j + 12, k + 8, selectedBlock);
		world.setBlock(i + 9, j + 12, k + 18, selectedBlock);
		world.setBlock(i + 9, j + 13, k + 8, selectedBlock);
		world.setBlock(i + 9, j + 13, k + 18, selectedBlock);
		world.setBlock(i + 9, j + 14, k + 9, selectedBlock);
		world.setBlock(i + 9, j + 14, k + 10, selectedBlock);
		world.setBlock(i + 9, j + 14, k + 16, selectedBlock);
		world.setBlock(i + 9, j + 14, k + 17, selectedBlock);
		world.setBlock(i + 9, j + 15, k + 9, selectedBlock);
		world.setBlock(i + 9, j + 15, k + 10, selectedBlock);
		world.setBlock(i + 9, j + 15, k + 16, selectedBlock);
		world.setBlock(i + 9, j + 15, k + 17, selectedBlock);
		world.setBlock(i + 9, j + 16, k + 11, selectedBlock);
		world.setBlock(i + 9, j + 16, k + 12, selectedBlock);
		world.setBlock(i + 9, j + 16, k + 13, selectedBlock);
		world.setBlock(i + 9, j + 16, k + 14, selectedBlock);
		world.setBlock(i + 9, j + 16, k + 15, selectedBlock);
		world.setBlock(i + 9, j + 17, k + 11, selectedBlock);
		world.setBlock(i + 9, j + 17, k + 12, selectedBlock);
		world.setBlock(i + 9, j + 17, k + 13, selectedBlock);
		world.setBlock(i + 9, j + 17, k + 14, selectedBlock);
		world.setBlock(i + 9, j + 17, k + 15, selectedBlock);
		world.setBlock(i + 10, j + 2, k + 4, selectedBlock);
		world.setBlock(i + 10, j + 2, k + 22, selectedBlock);
		world.setBlock(i + 10, j + 3, k + 4, selectedBlock);
		world.setBlock(i + 10, j + 3, k + 22, selectedBlock);
		world.setBlock(i + 10, j + 4, k + 4, selectedBlock);
		world.setBlock(i + 10, j + 4, k + 22, selectedBlock);
		world.setBlock(i + 10, j + 5, k + 4, selectedBlock);
		world.setBlock(i + 10, j + 5, k + 22, selectedBlock);
		world.setBlock(i + 10, j + 6, k + 4, selectedBlock);
		world.setBlock(i + 10, j + 6, k + 22, selectedBlock);
		world.setBlock(i + 10, j + 7, k + 4, selectedBlock);
		world.setBlock(i + 10, j + 7, k + 22, selectedBlock);
		world.setBlock(i + 10, j + 8, k + 4, selectedBlock);
		world.setBlock(i + 10, j + 8, k + 5, selectedBlock);
		world.setBlock(i + 10, j + 8, k + 21, selectedBlock);
		world.setBlock(i + 10, j + 8, k + 22, selectedBlock);
		world.setBlock(i + 10, j + 9, k + 5, selectedBlock);
		world.setBlock(i + 10, j + 9, k + 21, selectedBlock);
		world.setBlock(i + 10, j + 10, k + 6, selectedBlock);
		world.setBlock(i + 10, j + 10, k + 20, selectedBlock);
		world.setBlock(i + 10, j + 11, k + 6, selectedBlock);
		world.setBlock(i + 10, j + 11, k + 20, selectedBlock);
		world.setBlock(i + 10, j + 12, k + 7, selectedBlock);
		world.setBlock(i + 10, j + 12, k + 19, selectedBlock);
		world.setBlock(i + 10, j + 13, k + 7, selectedBlock);
		world.setBlock(i + 10, j + 13, k + 19, selectedBlock);
		world.setBlock(i + 10, j + 14, k + 8, selectedBlock);
		world.setBlock(i + 10, j + 14, k + 18, selectedBlock);
		world.setBlock(i + 10, j + 15, k + 8, selectedBlock);
		world.setBlock(i + 10, j + 15, k + 9, selectedBlock);
		world.setBlock(i + 10, j + 15, k + 17, selectedBlock);
		world.setBlock(i + 10, j + 15, k + 18, selectedBlock);
		world.setBlock(i + 10, j + 16, k + 10, selectedBlock);
		world.setBlock(i + 10, j + 16, k + 16, selectedBlock);
		world.setBlock(i + 10, j + 17, k + 10, selectedBlock);
		world.setBlock(i + 10, j + 17, k + 16, selectedBlock);
		world.setBlock(i + 10, j + 18, k + 11, selectedBlock);
		world.setBlock(i + 10, j + 18, k + 12, selectedBlock);
		world.setBlock(i + 10, j + 18, k + 13, selectedBlock);
		world.setBlock(i + 10, j + 18, k + 14, selectedBlock);
		world.setBlock(i + 10, j + 18, k + 15, selectedBlock);
		world.setBlock(i + 10, j + 19, k + 11, selectedBlock);
		world.setBlock(i + 10, j + 19, k + 12, selectedBlock);
		world.setBlock(i + 10, j + 19, k + 13, selectedBlock);
		world.setBlock(i + 10, j + 19, k + 14, selectedBlock);
		world.setBlock(i + 10, j + 19, k + 15, selectedBlock);
		world.setBlock(i + 11, j + 2, k + 3, selectedBlock);
		world.setBlock(i + 11, j + 2, k + 23, selectedBlock);
		world.setBlock(i + 11, j + 3, k + 3, selectedBlock);
		world.setBlock(i + 11, j + 3, k + 23, selectedBlock);
		world.setBlock(i + 11, j + 4, k + 3, selectedBlock);
		world.setBlock(i + 11, j + 4, k + 23, selectedBlock);
		world.setBlock(i + 11, j + 5, k + 3, selectedBlock);
		world.setBlock(i + 11, j + 5, k + 23, selectedBlock);
		world.setBlock(i + 11, j + 6, k + 3, selectedBlock);
		world.setBlock(i + 11, j + 6, k + 23, selectedBlock);
		world.setBlock(i + 11, j + 7, k + 3, selectedBlock);
		world.setBlock(i + 11, j + 7, k + 23, selectedBlock);
		world.setBlock(i + 11, j + 8, k + 3, selectedBlock);
		world.setBlock(i + 11, j + 8, k + 4, selectedBlock);
		world.setBlock(i + 11, j + 8, k + 22, selectedBlock);
		world.setBlock(i + 11, j + 8, k + 23, selectedBlock);
		world.setBlock(i + 11, j + 9, k + 4, selectedBlock);
		world.setBlock(i + 11, j + 9, k + 5, selectedBlock);
		world.setBlock(i + 11, j + 9, k + 21, selectedBlock);
		world.setBlock(i + 11, j + 9, k + 22, selectedBlock);
		world.setBlock(i + 11, j + 10, k + 6, selectedBlock);
		world.setBlock(i + 11, j + 10, k + 20, selectedBlock);
		world.setBlock(i + 11, j + 11, k + 6, selectedBlock);
		world.setBlock(i + 11, j + 11, k + 20, selectedBlock);
		world.setBlock(i + 11, j + 12, k + 7, selectedBlock);
		world.setBlock(i + 11, j + 12, k + 19, selectedBlock);
		world.setBlock(i + 11, j + 13, k + 7, selectedBlock);
		world.setBlock(i + 11, j + 13, k + 19, selectedBlock);
		world.setBlock(i + 11, j + 14, k + 8, selectedBlock);
		world.setBlock(i + 11, j + 14, k + 18, selectedBlock);
		world.setBlock(i + 11, j + 15, k + 8, selectedBlock);
		world.setBlock(i + 11, j + 15, k + 18, selectedBlock);
		world.setBlock(i + 11, j + 16, k + 9, selectedBlock);
		world.setBlock(i + 11, j + 16, k + 17, selectedBlock);
		world.setBlock(i + 11, j + 17, k + 9, selectedBlock);
		world.setBlock(i + 11, j + 17, k + 17, selectedBlock);
		world.setBlock(i + 11, j + 18, k + 10, selectedBlock);
		world.setBlock(i + 11, j + 18, k + 16, selectedBlock);
		world.setBlock(i + 11, j + 19, k + 10, selectedBlock);
		world.setBlock(i + 11, j + 19, k + 11, selectedBlock);
		world.setBlock(i + 11, j + 19, k + 15, selectedBlock);
		world.setBlock(i + 11, j + 19, k + 16, selectedBlock);
		world.setBlock(i + 11, j + 20, k + 12, selectedBlock);
		world.setBlock(i + 11, j + 20, k + 13, selectedBlock);
		world.setBlock(i + 11, j + 20, k + 14, selectedBlock);
		world.setBlock(i + 11, j + 21, k + 12, selectedBlock);
		world.setBlock(i + 11, j + 21, k + 13, selectedBlock);
		world.setBlock(i + 11, j + 21, k + 14, selectedBlock);
		if (randInt <= 8) {
			int chestX = i + 12;
			int chestY = j + 1;
			int chestZ = k + 13;
			int chestRand = (int) (Math.random() * Math.floor(2));
			boolean isBigChest = (chestRand == 1) ? true : false;
			String chestString = chestX + " " + chestY + " " + chestZ;
			LDTreasure.addChest(world, rand, chestX, chestY, chestZ,
					isBigChest,
					Treasures.pickChestType());
		}
		world.setBlock(i + 12, j + 2, k + 3, selectedBlock);
		int mobX = i + 12;
		int mobY = j + 2;
		int mobZ = k + 13;
		String mobString = mobX + " " + mobY + " " + mobZ;
		world.setBlock(mobX, mobY, mobZ, Block.mobSpawner.blockID);
		TileEntityMobSpawner tileentitymobspawner = (TileEntityMobSpawner) world
				.getBlockTileEntity(mobX, mobY, mobZ);
		if (tileentitymobspawner != null)
		{
			tileentitymobspawner.getSpawnerLogic().setMobID(
					DungeonHooks.getRandomDungeonMob(rand));
		} else {
			System.err.println("Failed to fetch mob spawner at: " + mobString);
		}
		world.setBlock(i + 12, j + 2, k + 23, selectedBlock);
		world.setBlock(i + 12, j + 3, k + 3, selectedBlock);
		world.setBlock(i + 12, j + 3, k + 23, selectedBlock);
		world.setBlock(i + 12, j + 4, k + 3, selectedBlock);
		world.setBlock(i + 12, j + 4, k + 23, selectedBlock);
		world.setBlock(i + 12, j + 5, k + 3, selectedBlock);
		world.setBlock(i + 12, j + 5, k + 23, selectedBlock);
		world.setBlock(i + 12, j + 6, k + 3, selectedBlock);
		world.setBlock(i + 12, j + 6, k + 23, selectedBlock);
		world.setBlock(i + 12, j + 7, k + 3, selectedBlock);
		world.setBlock(i + 12, j + 7, k + 23, selectedBlock);
		world.setBlock(i + 12, j + 8, k + 3, selectedBlock);
		world.setBlock(i + 12, j + 8, k + 4, selectedBlock);
		world.setBlock(i + 12, j + 8, k + 22, selectedBlock);
		world.setBlock(i + 12, j + 8, k + 23, selectedBlock);
		world.setBlock(i + 12, j + 9, k + 4, selectedBlock);
		world.setBlock(i + 12, j + 9, k + 22, selectedBlock);
		world.setBlock(i + 12, j + 10, k + 5, selectedBlock);
		world.setBlock(i + 12, j + 10, k + 21, selectedBlock);
		world.setBlock(i + 12, j + 11, k + 5, selectedBlock);
		world.setBlock(i + 12, j + 11, k + 21, selectedBlock);
		world.setBlock(i + 12, j + 12, k + 6, selectedBlock);
		world.setBlock(i + 12, j + 12, k + 20, selectedBlock);
		world.setBlock(i + 12, j + 13, k + 6, selectedBlock);
		world.setBlock(i + 12, j + 13, k + 20, selectedBlock);
		world.setBlock(i + 12, j + 14, k + 7, selectedBlock);
		world.setBlock(i + 12, j + 14, k + 19, selectedBlock);
		world.setBlock(i + 12, j + 15, k + 7, selectedBlock);
		world.setBlock(i + 12, j + 15, k + 19, selectedBlock);
		world.setBlock(i + 12, j + 16, k + 8, selectedBlock);
		world.setBlock(i + 12, j + 16, k + 18, selectedBlock);
		world.setBlock(i + 12, j + 17, k + 8, selectedBlock);
		world.setBlock(i + 12, j + 17, k + 18, selectedBlock);
		world.setBlock(i + 12, j + 18, k + 9, selectedBlock);
		world.setBlock(i + 12, j + 18, k + 17, selectedBlock);
		world.setBlock(i + 12, j + 19, k + 9, selectedBlock);
		world.setBlock(i + 12, j + 19, k + 10, selectedBlock);
		world.setBlock(i + 12, j + 19, k + 16, selectedBlock);
		world.setBlock(i + 12, j + 19, k + 17, selectedBlock);
		world.setBlock(i + 12, j + 20, k + 11, selectedBlock);
		world.setBlock(i + 12, j + 20, k + 15, selectedBlock);
		world.setBlock(i + 12, j + 21, k + 11, selectedBlock);
		world.setBlock(i + 12, j + 21, k + 15, selectedBlock);
		selectedBlock = (randBlockInt <= 2) ? Blocks.desertCrystal.blockID
				: Blocks.lostCrystal.blockID;
		world.setBlock(i + 12, j + 22, k + 12, selectedBlock);
		world.setBlock(i + 12, j + 22, k + 13, selectedBlock);
		world.setBlock(i + 12, j + 22, k + 14, selectedBlock);
		world.setBlock(i + 12, j + 23, k + 12, selectedBlock);
		world.setBlock(i + 12, j + 23, k + 13, selectedBlock);
		world.setBlock(i + 12, j + 23, k + 14, selectedBlock);
		world.setBlock(i + 13, j + 2, k + 3, selectedBlock);
		world.setBlock(i + 13, j + 2, k + 23, selectedBlock);
		world.setBlock(i + 13, j + 3, k + 3, selectedBlock);
		world.setBlock(i + 13, j + 3, k + 23, selectedBlock);
		world.setBlock(i + 13, j + 4, k + 3, selectedBlock);
		world.setBlock(i + 13, j + 4, k + 23, selectedBlock);
		world.setBlock(i + 13, j + 5, k + 3, selectedBlock);
		world.setBlock(i + 13, j + 5, k + 23, selectedBlock);
		world.setBlock(i + 13, j + 6, k + 3, selectedBlock);
		world.setBlock(i + 13, j + 6, k + 23, selectedBlock);
		world.setBlock(i + 13, j + 7, k + 3, selectedBlock);
		world.setBlock(i + 13, j + 7, k + 23, selectedBlock);
		world.setBlock(i + 13, j + 8, k + 3, selectedBlock);
		world.setBlock(i + 13, j + 8, k + 4, selectedBlock);
		world.setBlock(i + 13, j + 8, k + 22, selectedBlock);
		world.setBlock(i + 13, j + 8, k + 23, selectedBlock);
		world.setBlock(i + 13, j + 9, k + 4, selectedBlock);
		world.setBlock(i + 13, j + 9, k + 22, selectedBlock);
		world.setBlock(i + 13, j + 10, k + 5, selectedBlock);
		world.setBlock(i + 13, j + 10, k + 21, selectedBlock);
		world.setBlock(i + 13, j + 11, k + 5, selectedBlock);
		world.setBlock(i + 13, j + 11, k + 21, selectedBlock);
		world.setBlock(i + 13, j + 12, k + 6, selectedBlock);
		world.setBlock(i + 13, j + 12, k + 20, selectedBlock);
		world.setBlock(i + 13, j + 13, k + 6, selectedBlock);
		world.setBlock(i + 13, j + 13, k + 20, selectedBlock);
		world.setBlock(i + 13, j + 14, k + 7, selectedBlock);
		world.setBlock(i + 13, j + 14, k + 19, selectedBlock);
		world.setBlock(i + 13, j + 15, k + 7, selectedBlock);
		world.setBlock(i + 13, j + 15, k + 19, selectedBlock);
		world.setBlock(i + 13, j + 16, k + 8, selectedBlock);
		world.setBlock(i + 13, j + 16, k + 18, selectedBlock);
		world.setBlock(i + 13, j + 17, k + 8, selectedBlock);
		world.setBlock(i + 13, j + 17, k + 18, selectedBlock);
		world.setBlock(i + 13, j + 18, k + 9, selectedBlock);
		world.setBlock(i + 13, j + 18, k + 17, selectedBlock);
		world.setBlock(i + 13, j + 19, k + 9, selectedBlock);
		world.setBlock(i + 13, j + 19, k + 17, selectedBlock);
		world.setBlock(i + 13, j + 20, k + 10, selectedBlock);
		world.setBlock(i + 13, j + 20, k + 16, selectedBlock);
		world.setBlock(i + 13, j + 21, k + 10, selectedBlock);
		world.setBlock(i + 13, j + 21, k + 16, selectedBlock);
		world.setBlock(i + 13, j + 22, k + 11, selectedBlock);
		world.setBlock(i + 13, j + 22, k + 15, selectedBlock);
		world.setBlock(i + 13, j + 23, k + 11, selectedBlock);
		world.setBlock(i + 13, j + 23, k + 15, selectedBlock);
		world.setBlock(i + 13, j + 24, k + 12, selectedBlock);
		world.setBlock(i + 13, j + 24, k + 13, selectedBlock);
		world.setBlock(i + 13, j + 24, k + 14, selectedBlock);
		world.setBlock(i + 14, j + 2, k + 3, selectedBlock);
		world.setBlock(i + 14, j + 2, k + 23, selectedBlock);
		world.setBlock(i + 14, j + 3, k + 3, selectedBlock);
		world.setBlock(i + 14, j + 3, k + 23, selectedBlock);
		world.setBlock(i + 14, j + 4, k + 3, selectedBlock);
		world.setBlock(i + 14, j + 4, k + 23, selectedBlock);
		world.setBlock(i + 14, j + 5, k + 3, selectedBlock);
		world.setBlock(i + 14, j + 5, k + 23, selectedBlock);
		world.setBlock(i + 14, j + 6, k + 3, selectedBlock);
		world.setBlock(i + 14, j + 6, k + 23, selectedBlock);
		world.setBlock(i + 14, j + 7, k + 3, selectedBlock);
		world.setBlock(i + 14, j + 7, k + 23, selectedBlock);
		world.setBlock(i + 14, j + 8, k + 3, selectedBlock);
		world.setBlock(i + 14, j + 8, k + 4, selectedBlock);
		world.setBlock(i + 14, j + 8, k + 22, selectedBlock);
		world.setBlock(i + 14, j + 8, k + 23, selectedBlock);
		world.setBlock(i + 14, j + 9, k + 4, selectedBlock);
		world.setBlock(i + 14, j + 9, k + 22, selectedBlock);
		world.setBlock(i + 14, j + 10, k + 5, selectedBlock);
		world.setBlock(i + 14, j + 10, k + 21, selectedBlock);
		world.setBlock(i + 14, j + 11, k + 5, selectedBlock);
		world.setBlock(i + 14, j + 11, k + 21, selectedBlock);
		world.setBlock(i + 14, j + 12, k + 6, selectedBlock);
		world.setBlock(i + 14, j + 12, k + 20, selectedBlock);
		world.setBlock(i + 14, j + 13, k + 6, selectedBlock);
		world.setBlock(i + 14, j + 13, k + 20, selectedBlock);
		world.setBlock(i + 14, j + 14, k + 7, selectedBlock);
		world.setBlock(i + 14, j + 14, k + 19, selectedBlock);
		world.setBlock(i + 14, j + 15, k + 7, selectedBlock);
		world.setBlock(i + 14, j + 15, k + 19, selectedBlock);
		world.setBlock(i + 14, j + 16, k + 8, selectedBlock);
		world.setBlock(i + 14, j + 16, k + 18, selectedBlock);
		world.setBlock(i + 14, j + 17, k + 8, selectedBlock);
		world.setBlock(i + 14, j + 17, k + 18, selectedBlock);
		world.setBlock(i + 14, j + 18, k + 9, selectedBlock);
		world.setBlock(i + 14, j + 18, k + 17, selectedBlock);
		world.setBlock(i + 14, j + 19, k + 9, selectedBlock);
		world.setBlock(i + 14, j + 19, k + 17, selectedBlock);
		world.setBlock(i + 14, j + 20, k + 10, selectedBlock);
		world.setBlock(i + 14, j + 20, k + 16, selectedBlock);
		world.setBlock(i + 14, j + 21, k + 10, selectedBlock);
		world.setBlock(i + 14, j + 21, k + 16, selectedBlock);
		world.setBlock(i + 14, j + 22, k + 11, selectedBlock);
		world.setBlock(i + 14, j + 22, k + 15, selectedBlock);
		world.setBlock(i + 14, j + 23, k + 11, selectedBlock);
		world.setBlock(i + 14, j + 23, k + 15, selectedBlock);
		world.setBlock(i + 14, j + 24, k + 12, selectedBlock);
		world.setBlock(i + 14, j + 24, k + 13, Block.blockLapis.blockID);
		world.setBlock(i + 14, j + 24, k + 14, selectedBlock);
		
		generate2(world, rand, i, j, k);
		return true;
	}
	
	public boolean generate2(World world, Random rand, int i, int j, int k) {
		selectedBlock = (randBlockInt <= 2) ? Blocks.desertCrystal.blockID
				: Blocks.lostCrystal.blockID;
		world.setBlock(i + 15, j + 2, k + 3, selectedBlock);
		world.setBlock(i + 15, j + 2, k + 23, selectedBlock);
		world.setBlock(i + 15, j + 3, k + 3, selectedBlock);
		world.setBlock(i + 15, j + 3, k + 23, selectedBlock);
		world.setBlock(i + 15, j + 4, k + 3, selectedBlock);
		world.setBlock(i + 15, j + 4, k + 23, selectedBlock);
		world.setBlock(i + 15, j + 5, k + 3, selectedBlock);
		world.setBlock(i + 15, j + 5, k + 23, selectedBlock);
		world.setBlock(i + 15, j + 6, k + 3, selectedBlock);
		world.setBlock(i + 15, j + 6, k + 23, selectedBlock);
		world.setBlock(i + 15, j + 7, k + 3, selectedBlock);
		world.setBlock(i + 15, j + 7, k + 23, selectedBlock);
		world.setBlock(i + 15, j + 8, k + 3, selectedBlock);
		world.setBlock(i + 15, j + 8, k + 4, selectedBlock);
		world.setBlock(i + 15, j + 8, k + 22, selectedBlock);
		world.setBlock(i + 15, j + 8, k + 23, selectedBlock);
		world.setBlock(i + 15, j + 9, k + 4, selectedBlock);
		world.setBlock(i + 15, j + 9, k + 22, selectedBlock);
		world.setBlock(i + 15, j + 10, k + 5, selectedBlock);
		world.setBlock(i + 15, j + 10, k + 21, selectedBlock);
		world.setBlock(i + 15, j + 11, k + 5, selectedBlock);
		world.setBlock(i + 15, j + 11, k + 21, selectedBlock);
		world.setBlock(i + 15, j + 12, k + 6, selectedBlock);
		world.setBlock(i + 15, j + 12, k + 20, selectedBlock);
		world.setBlock(i + 15, j + 13, k + 6, selectedBlock);
		world.setBlock(i + 15, j + 13, k + 20, selectedBlock);
		world.setBlock(i + 15, j + 14, k + 7, selectedBlock);
		world.setBlock(i + 15, j + 14, k + 19, selectedBlock);
		world.setBlock(i + 15, j + 15, k + 7, selectedBlock);
		world.setBlock(i + 15, j + 15, k + 19, selectedBlock);
		world.setBlock(i + 15, j + 16, k + 8, selectedBlock);
		world.setBlock(i + 15, j + 16, k + 18, selectedBlock);
		world.setBlock(i + 15, j + 17, k + 8, selectedBlock);
		world.setBlock(i + 15, j + 17, k + 18, selectedBlock);
		world.setBlock(i + 15, j + 18, k + 9, selectedBlock);
		world.setBlock(i + 15, j + 18, k + 17, selectedBlock);
		world.setBlock(i + 15, j + 19, k + 9, selectedBlock);
		world.setBlock(i + 15, j + 19, k + 17, selectedBlock);
		world.setBlock(i + 15, j + 20, k + 10, selectedBlock);
		world.setBlock(i + 15, j + 20, k + 16, selectedBlock);
		world.setBlock(i + 15, j + 21, k + 10, selectedBlock);
		world.setBlock(i + 15, j + 21, k + 16, selectedBlock);
		world.setBlock(i + 15, j + 22, k + 11, selectedBlock);
		world.setBlock(i + 15, j + 22, k + 15, selectedBlock);
		world.setBlock(i + 15, j + 23, k + 11, selectedBlock);
		world.setBlock(i + 15, j + 23, k + 15, selectedBlock);
		world.setBlock(i + 15, j + 24, k + 12, selectedBlock);
		world.setBlock(i + 15, j + 24, k + 13, selectedBlock);
		world.setBlock(i + 15, j + 24, k + 14, selectedBlock);
		world.setBlock(i + 16, j + 2, k + 3, selectedBlock);
		world.setBlock(i + 16, j + 2, k + 23, selectedBlock);
		world.setBlock(i + 16, j + 3, k + 3, selectedBlock);
		world.setBlock(i + 16, j + 3, k + 23, selectedBlock);
		world.setBlock(i + 16, j + 4, k + 3, selectedBlock);
		world.setBlock(i + 16, j + 4, k + 23, selectedBlock);
		world.setBlock(i + 16, j + 5, k + 3, selectedBlock);
		world.setBlock(i + 16, j + 5, k + 23, selectedBlock);
		world.setBlock(i + 16, j + 6, k + 3, selectedBlock);
		world.setBlock(i + 16, j + 6, k + 23, selectedBlock);
		world.setBlock(i + 16, j + 7, k + 3, selectedBlock);
		world.setBlock(i + 16, j + 7, k + 23, selectedBlock);
		world.setBlock(i + 16, j + 8, k + 3, selectedBlock);
		world.setBlock(i + 16, j + 8, k + 4, selectedBlock);
		world.setBlock(i + 16, j + 8, k + 22, selectedBlock);
		world.setBlock(i + 16, j + 8, k + 23, selectedBlock);
		world.setBlock(i + 16, j + 9, k + 4, selectedBlock);
		world.setBlock(i + 16, j + 9, k + 22, selectedBlock);
		world.setBlock(i + 16, j + 10, k + 5, selectedBlock);
		world.setBlock(i + 16, j + 10, k + 21, selectedBlock);
		world.setBlock(i + 16, j + 11, k + 5, selectedBlock);
		world.setBlock(i + 16, j + 11, k + 21, selectedBlock);
		world.setBlock(i + 16, j + 12, k + 6, selectedBlock);
		world.setBlock(i + 16, j + 12, k + 20, selectedBlock);
		world.setBlock(i + 16, j + 13, k + 6, selectedBlock);
		world.setBlock(i + 16, j + 13, k + 20, selectedBlock);
		world.setBlock(i + 16, j + 14, k + 7, selectedBlock);
		world.setBlock(i + 16, j + 14, k + 19, selectedBlock);
		world.setBlock(i + 16, j + 15, k + 7, selectedBlock);
		world.setBlock(i + 16, j + 15, k + 19, selectedBlock);
		world.setBlock(i + 16, j + 16, k + 8, selectedBlock);
		world.setBlock(i + 16, j + 16, k + 18, selectedBlock);
		world.setBlock(i + 16, j + 17, k + 8, selectedBlock);
		world.setBlock(i + 16, j + 17, k + 18, selectedBlock);
		world.setBlock(i + 16, j + 18, k + 9, selectedBlock);
		world.setBlock(i + 16, j + 18, k + 17, selectedBlock);
		world.setBlock(i + 16, j + 19, k + 9, selectedBlock);
		world.setBlock(i + 16, j + 19, k + 10, selectedBlock);
		world.setBlock(i + 16, j + 19, k + 16, selectedBlock);
		world.setBlock(i + 16, j + 19, k + 17, selectedBlock);
		world.setBlock(i + 16, j + 20, k + 11, selectedBlock);
		world.setBlock(i + 16, j + 20, k + 15, selectedBlock);
		world.setBlock(i + 16, j + 21, k + 11, selectedBlock);
		world.setBlock(i + 16, j + 21, k + 15, selectedBlock);
		world.setBlock(i + 16, j + 22, k + 12, selectedBlock);
		world.setBlock(i + 16, j + 22, k + 13, selectedBlock);
		world.setBlock(i + 16, j + 22, k + 14, selectedBlock);
		world.setBlock(i + 16, j + 23, k + 12, selectedBlock);
		world.setBlock(i + 16, j + 23, k + 13, selectedBlock);
		world.setBlock(i + 16, j + 23, k + 14, selectedBlock);
		world.setBlock(i + 18, j + 2, k + 4, selectedBlock);
		world.setBlock(i + 18, j + 2, k + 22, selectedBlock);
		world.setBlock(i + 18, j + 3, k + 4, selectedBlock);
		world.setBlock(i + 18, j + 3, k + 22, selectedBlock);
		world.setBlock(i + 18, j + 4, k + 4, selectedBlock);
		world.setBlock(i + 18, j + 4, k + 22, selectedBlock);
		world.setBlock(i + 18, j + 5, k + 4, selectedBlock);
		world.setBlock(i + 18, j + 5, k + 22, selectedBlock);
		world.setBlock(i + 18, j + 6, k + 4, selectedBlock);
		world.setBlock(i + 18, j + 6, k + 22, selectedBlock);
		world.setBlock(i + 18, j + 7, k + 4, selectedBlock);
		world.setBlock(i + 18, j + 7, k + 22, selectedBlock);
		world.setBlock(i + 18, j + 8, k + 4, selectedBlock);
		world.setBlock(i + 18, j + 8, k + 5, selectedBlock);
		world.setBlock(i + 18, j + 8, k + 21, selectedBlock);
		world.setBlock(i + 18, j + 8, k + 22, selectedBlock);
		world.setBlock(i + 18, j + 9, k + 5, selectedBlock);
		world.setBlock(i + 18, j + 9, k + 21, selectedBlock);
		world.setBlock(i + 18, j + 10, k + 6, selectedBlock);
		world.setBlock(i + 18, j + 10, k + 20, selectedBlock);
		world.setBlock(i + 18, j + 11, k + 6, selectedBlock);
		world.setBlock(i + 18, j + 11, k + 20, selectedBlock);
		world.setBlock(i + 18, j + 12, k + 7, selectedBlock);
		world.setBlock(i + 18, j + 12, k + 19, selectedBlock);
		world.setBlock(i + 18, j + 13, k + 7, selectedBlock);
		world.setBlock(i + 18, j + 13, k + 19, selectedBlock);
		world.setBlock(i + 18, j + 14, k + 8, selectedBlock);
		world.setBlock(i + 18, j + 14, k + 18, selectedBlock);
		world.setBlock(i + 18, j + 15, k + 8, selectedBlock);
		world.setBlock(i + 18, j + 15, k + 9, selectedBlock);
		world.setBlock(i + 18, j + 15, k + 17, selectedBlock);
		world.setBlock(i + 18, j + 15, k + 18, selectedBlock);
		world.setBlock(i + 18, j + 16, k + 10, selectedBlock);
		world.setBlock(i + 18, j + 16, k + 16, selectedBlock);
		world.setBlock(i + 18, j + 17, k + 10, selectedBlock);
		world.setBlock(i + 18, j + 17, k + 16, selectedBlock);
		world.setBlock(i + 18, j + 18, k + 11, selectedBlock);
		world.setBlock(i + 18, j + 18, k + 12, selectedBlock);
		world.setBlock(i + 18, j + 18, k + 13, selectedBlock);
		world.setBlock(i + 18, j + 18, k + 14, selectedBlock);
		world.setBlock(i + 18, j + 18, k + 15, selectedBlock);
		world.setBlock(i + 18, j + 19, k + 11, selectedBlock);
		world.setBlock(i + 18, j + 19, k + 12, selectedBlock);
		world.setBlock(i + 18, j + 19, k + 13, selectedBlock);
		world.setBlock(i + 18, j + 19, k + 14, selectedBlock);
		world.setBlock(i + 18, j + 19, k + 15, selectedBlock);
		world.setBlock(i + 19, j + 2, k + 4, selectedBlock);
		world.setBlock(i + 19, j + 2, k + 22, selectedBlock);
		world.setBlock(i + 19, j + 3, k + 4, selectedBlock);
		world.setBlock(i + 19, j + 3, k + 22, selectedBlock);
		world.setBlock(i + 19, j + 4, k + 4, selectedBlock);
		world.setBlock(i + 19, j + 4, k + 22, selectedBlock);
		world.setBlock(i + 19, j + 5, k + 4, selectedBlock);
		world.setBlock(i + 19, j + 5, k + 22, selectedBlock);
		world.setBlock(i + 19, j + 6, k + 4, selectedBlock);
		world.setBlock(i + 19, j + 6, k + 22, selectedBlock);
		world.setBlock(i + 19, j + 7, k + 4, selectedBlock);
		world.setBlock(i + 19, j + 7, k + 22, selectedBlock);
		world.setBlock(i + 19, j + 8, k + 4, selectedBlock);
		world.setBlock(i + 19, j + 8, k + 5, selectedBlock);
		world.setBlock(i + 19, j + 8, k + 21, selectedBlock);
		world.setBlock(i + 19, j + 8, k + 22, selectedBlock);
		world.setBlock(i + 19, j + 9, k + 5, selectedBlock);
		world.setBlock(i + 19, j + 9, k + 6, selectedBlock);
		world.setBlock(i + 19, j + 9, k + 20, selectedBlock);
		world.setBlock(i + 19, j + 9, k + 21, selectedBlock);
		world.setBlock(i + 19, j + 10, k + 7, selectedBlock);
		world.setBlock(i + 19, j + 10, k + 19, selectedBlock);
		world.setBlock(i + 19, j + 11, k + 7, selectedBlock);
		world.setBlock(i + 19, j + 11, k + 19, selectedBlock);
		world.setBlock(i + 19, j + 12, k + 8, selectedBlock);
		world.setBlock(i + 19, j + 12, k + 18, selectedBlock);
		world.setBlock(i + 19, j + 13, k + 8, selectedBlock);
		world.setBlock(i + 19, j + 13, k + 18, selectedBlock);
		world.setBlock(i + 19, j + 14, k + 9, selectedBlock);
		world.setBlock(i + 19, j + 14, k + 10, selectedBlock);
		world.setBlock(i + 19, j + 14, k + 16, selectedBlock);
		world.setBlock(i + 19, j + 14, k + 17, selectedBlock);
		world.setBlock(i + 19, j + 15, k + 9, selectedBlock);
		world.setBlock(i + 19, j + 15, k + 10, selectedBlock);
		world.setBlock(i + 19, j + 15, k + 16, selectedBlock);
		world.setBlock(i + 19, j + 15, k + 17, selectedBlock);
		world.setBlock(i + 19, j + 16, k + 11, selectedBlock);
		world.setBlock(i + 19, j + 16, k + 12, selectedBlock);
		world.setBlock(i + 19, j + 16, k + 13, selectedBlock);
		world.setBlock(i + 19, j + 16, k + 14, selectedBlock);
		world.setBlock(i + 19, j + 16, k + 15, selectedBlock);
		world.setBlock(i + 19, j + 17, k + 11, selectedBlock);
		world.setBlock(i + 19, j + 17, k + 12, selectedBlock);
		world.setBlock(i + 19, j + 17, k + 13, selectedBlock);
		world.setBlock(i + 19, j + 17, k + 14, selectedBlock);
		world.setBlock(i + 19, j + 17, k + 15, selectedBlock);
		world.setBlock(i + 20, j + 2, k + 5, selectedBlock);
		world.setBlock(i + 20, j + 2, k + 21, selectedBlock);
		world.setBlock(i + 20, j + 3, k + 5, selectedBlock);
		world.setBlock(i + 20, j + 3, k + 21, selectedBlock);
		world.setBlock(i + 20, j + 4, k + 5, selectedBlock);
		world.setBlock(i + 20, j + 4, k + 21, selectedBlock);
		world.setBlock(i + 20, j + 5, k + 5, selectedBlock);
		world.setBlock(i + 20, j + 5, k + 21, selectedBlock);
		world.setBlock(i + 20, j + 6, k + 5, selectedBlock);
		world.setBlock(i + 20, j + 6, k + 21, selectedBlock);
		world.setBlock(i + 20, j + 7, k + 5, selectedBlock);
		world.setBlock(i + 20, j + 7, k + 21, selectedBlock);
		world.setBlock(i + 20, j + 8, k + 5, selectedBlock);
		world.setBlock(i + 20, j + 8, k + 6, selectedBlock);
		world.setBlock(i + 20, j + 8, k + 20, selectedBlock);
		world.setBlock(i + 20, j + 8, k + 21, selectedBlock);
		world.setBlock(i + 20, j + 9, k + 6, selectedBlock);
		world.setBlock(i + 20, j + 9, k + 20, selectedBlock);
		world.setBlock(i + 20, j + 10, k + 7, selectedBlock);
		world.setBlock(i + 20, j + 10, k + 8, selectedBlock);
		world.setBlock(i + 20, j + 10, k + 18, selectedBlock);
		world.setBlock(i + 20, j + 10, k + 19, selectedBlock);
		world.setBlock(i + 20, j + 11, k + 7, selectedBlock);
		world.setBlock(i + 20, j + 11, k + 8, selectedBlock);
		world.setBlock(i + 20, j + 11, k + 18, selectedBlock);
		world.setBlock(i + 20, j + 11, k + 19, selectedBlock);
		world.setBlock(i + 20, j + 12, k + 9, selectedBlock);
		world.setBlock(i + 20, j + 12, k + 10, selectedBlock);
		world.setBlock(i + 20, j + 12, k + 16, selectedBlock);
		world.setBlock(i + 20, j + 12, k + 17, selectedBlock);
		world.setBlock(i + 20, j + 13, k + 9, selectedBlock);
		world.setBlock(i + 20, j + 13, k + 10, selectedBlock);
		world.setBlock(i + 20, j + 13, k + 16, selectedBlock);
		world.setBlock(i + 20, j + 13, k + 17, selectedBlock);
		world.setBlock(i + 20, j + 14, k + 11, selectedBlock);
		world.setBlock(i + 20, j + 14, k + 12, selectedBlock);
		world.setBlock(i + 20, j + 14, k + 13, selectedBlock);
		world.setBlock(i + 20, j + 14, k + 14, selectedBlock);
		world.setBlock(i + 20, j + 14, k + 15, selectedBlock);
		world.setBlock(i + 20, j + 15, k + 11, selectedBlock);
		world.setBlock(i + 20, j + 15, k + 12, selectedBlock);
		world.setBlock(i + 20, j + 15, k + 13, selectedBlock);
		world.setBlock(i + 20, j + 15, k + 14, selectedBlock);
		world.setBlock(i + 20, j + 15, k + 15, selectedBlock);
		world.setBlock(i + 21, j + 2, k + 6, selectedBlock);
		world.setBlock(i + 21, j + 2, k + 20, selectedBlock);
		world.setBlock(i + 21, j + 3, k + 6, selectedBlock);
		world.setBlock(i + 21, j + 3, k + 20, selectedBlock);
		world.setBlock(i + 21, j + 4, k + 6, selectedBlock);
		world.setBlock(i + 21, j + 4, k + 20, selectedBlock);
		world.setBlock(i + 21, j + 5, k + 6, selectedBlock);
		world.setBlock(i + 21, j + 5, k + 20, selectedBlock);
		world.setBlock(i + 21, j + 6, k + 6, selectedBlock);
		world.setBlock(i + 21, j + 6, k + 20, selectedBlock);
		world.setBlock(i + 21, j + 7, k + 6, selectedBlock);
		world.setBlock(i + 21, j + 7, k + 20, selectedBlock);
		world.setBlock(i + 21, j + 8, k + 6, selectedBlock);
		world.setBlock(i + 21, j + 8, k + 7, selectedBlock);
		world.setBlock(i + 21, j + 8, k + 19, selectedBlock);
		world.setBlock(i + 21, j + 8, k + 20, selectedBlock);
		world.setBlock(i + 21, j + 9, k + 7, selectedBlock);
		world.setBlock(i + 21, j + 9, k + 8, selectedBlock);
		world.setBlock(i + 21, j + 9, k + 18, selectedBlock);
		world.setBlock(i + 21, j + 9, k + 19, selectedBlock);
		world.setBlock(i + 21, j + 10, k + 9, selectedBlock);
		world.setBlock(i + 21, j + 10, k + 10, selectedBlock);
		world.setBlock(i + 21, j + 10, k + 16, selectedBlock);
		world.setBlock(i + 21, j + 10, k + 17, selectedBlock);
		world.setBlock(i + 21, j + 11, k + 9, selectedBlock);
		world.setBlock(i + 21, j + 11, k + 10, selectedBlock);
		world.setBlock(i + 21, j + 11, k + 16, selectedBlock);
		world.setBlock(i + 21, j + 11, k + 17, selectedBlock);
		world.setBlock(i + 21, j + 12, k + 11, selectedBlock);
		world.setBlock(i + 21, j + 12, k + 12, selectedBlock);
		world.setBlock(i + 21, j + 12, k + 13, selectedBlock);
		world.setBlock(i + 21, j + 12, k + 14, selectedBlock);
		world.setBlock(i + 21, j + 12, k + 15, selectedBlock);
		world.setBlock(i + 21, j + 13, k + 11, selectedBlock);
		world.setBlock(i + 21, j + 13, k + 12, selectedBlock);
		world.setBlock(i + 21, j + 13, k + 13, selectedBlock);
		world.setBlock(i + 21, j + 13, k + 14, selectedBlock);
		world.setBlock(i + 21, j + 13, k + 15, selectedBlock);
		world.setBlock(i + 22, j + 2, k + 7, selectedBlock);
		world.setBlock(i + 22, j + 2, k + 19, selectedBlock);
		world.setBlock(i + 22, j + 3, k + 7, selectedBlock);
		world.setBlock(i + 22, j + 3, k + 19, selectedBlock);
		world.setBlock(i + 22, j + 4, k + 7, selectedBlock);
		world.setBlock(i + 22, j + 4, k + 19, selectedBlock);
		world.setBlock(i + 22, j + 5, k + 7, selectedBlock);
		world.setBlock(i + 22, j + 5, k + 19, selectedBlock);
		world.setBlock(i + 22, j + 6, k + 7, selectedBlock);
		world.setBlock(i + 22, j + 6, k + 19, selectedBlock);
		world.setBlock(i + 22, j + 7, k + 7, selectedBlock);
		world.setBlock(i + 22, j + 7, k + 19, selectedBlock);
		world.setBlock(i + 22, j + 8, k + 7, selectedBlock);
		world.setBlock(i + 22, j + 8, k + 8, selectedBlock);
		world.setBlock(i + 22, j + 8, k + 9, selectedBlock);
		world.setBlock(i + 22, j + 8, k + 17, selectedBlock);
		world.setBlock(i + 22, j + 8, k + 18, selectedBlock);
		world.setBlock(i + 22, j + 8, k + 19, selectedBlock);
		world.setBlock(i + 22, j + 9, k + 8, selectedBlock);
		world.setBlock(i + 22, j + 9, k + 9, selectedBlock);
		world.setBlock(i + 22, j + 9, k + 10, selectedBlock);
		world.setBlock(i + 22, j + 9, k + 16, selectedBlock);
		world.setBlock(i + 22, j + 9, k + 17, selectedBlock);
		world.setBlock(i + 22, j + 9, k + 18, selectedBlock);
		world.setBlock(i + 22, j + 10, k + 11, selectedBlock);
		world.setBlock(i + 22, j + 10, k + 12, selectedBlock);
		world.setBlock(i + 22, j + 10, k + 13, selectedBlock);
		world.setBlock(i + 22, j + 10, k + 14, selectedBlock);
		world.setBlock(i + 22, j + 10, k + 15, selectedBlock);
		world.setBlock(i + 22, j + 11, k + 11, selectedBlock);
		world.setBlock(i + 22, j + 11, k + 12, selectedBlock);
		world.setBlock(i + 22, j + 11, k + 13, selectedBlock);
		world.setBlock(i + 22, j + 11, k + 14, selectedBlock);
		world.setBlock(i + 22, j + 11, k + 15, selectedBlock);
		world.setBlock(i + 23, j + 2, k + 8, selectedBlock);
		world.setBlock(i + 23, j + 2, k + 9, selectedBlock);
		world.setBlock(i + 23, j + 2, k + 17, selectedBlock);
		world.setBlock(i + 23, j + 2, k + 18, selectedBlock);
		world.setBlock(i + 23, j + 3, k + 8, selectedBlock);
		world.setBlock(i + 23, j + 3, k + 9, selectedBlock);
		world.setBlock(i + 23, j + 3, k + 17, selectedBlock);
		world.setBlock(i + 23, j + 3, k + 18, selectedBlock);
		world.setBlock(i + 23, j + 4, k + 8, selectedBlock);
		world.setBlock(i + 23, j + 4, k + 9, selectedBlock);
		world.setBlock(i + 23, j + 4, k + 17, selectedBlock);
		world.setBlock(i + 23, j + 4, k + 18, selectedBlock);
		world.setBlock(i + 23, j + 5, k + 8, selectedBlock);
		world.setBlock(i + 23, j + 5, k + 9, selectedBlock);
		world.setBlock(i + 23, j + 5, k + 17, selectedBlock);
		world.setBlock(i + 23, j + 5, k + 18, selectedBlock);
		world.setBlock(i + 23, j + 6, k + 8, selectedBlock);
		world.setBlock(i + 23, j + 6, k + 9, selectedBlock);
		world.setBlock(i + 23, j + 6, k + 17, selectedBlock);
		world.setBlock(i + 23, j + 6, k + 18, selectedBlock);
		world.setBlock(i + 23, j + 7, k + 8, selectedBlock);
		world.setBlock(i + 23, j + 7, k + 9, selectedBlock);
		world.setBlock(i + 23, j + 7, k + 17, selectedBlock);
		world.setBlock(i + 23, j + 7, k + 18, selectedBlock);
		world.setBlock(i + 23, j + 8, k + 8, selectedBlock);
		world.setBlock(i + 23, j + 8, k + 9, selectedBlock);
		world.setBlock(i + 23, j + 8, k + 10, selectedBlock);
		world.setBlock(i + 23, j + 8, k + 11, selectedBlock);
		world.setBlock(i + 23, j + 8, k + 12, selectedBlock);
		world.setBlock(i + 23, j + 8, k + 13, selectedBlock);
		world.setBlock(i + 23, j + 8, k + 14, selectedBlock);
		world.setBlock(i + 23, j + 8, k + 15, selectedBlock);
		world.setBlock(i + 23, j + 8, k + 16, selectedBlock);
		world.setBlock(i + 23, j + 8, k + 17, selectedBlock);
		world.setBlock(i + 23, j + 8, k + 18, selectedBlock);
		world.setBlock(i + 23, j + 9, k + 10, selectedBlock);
		world.setBlock(i + 23, j + 9, k + 11, selectedBlock);
		world.setBlock(i + 23, j + 9, k + 12, selectedBlock);
		world.setBlock(i + 23, j + 9, k + 13, selectedBlock);
		world.setBlock(i + 23, j + 9, k + 14, selectedBlock);
		world.setBlock(i + 23, j + 9, k + 15, selectedBlock);
		world.setBlock(i + 23, j + 9, k + 16, selectedBlock);
		world.setBlock(i + 24, j + 2, k + 10, selectedBlock);
		world.setBlock(i + 24, j + 2, k + 11, selectedBlock);
		world.setBlock(i + 24, j + 2, k + 14, selectedBlock);
		world.setBlock(i + 24, j + 2, k + 15, selectedBlock);
		world.setBlock(i + 24, j + 2, k + 16, selectedBlock);
		world.setBlock(i + 24, j + 3, k + 10, selectedBlock);
		world.setBlock(i + 24, j + 3, k + 11, selectedBlock);
		world.setBlock(i + 24, j + 3, k + 14, selectedBlock);
		world.setBlock(i + 24, j + 3, k + 15, selectedBlock);
		world.setBlock(i + 24, j + 3, k + 16, selectedBlock);
		world.setBlock(i + 24, j + 4, k + 10, selectedBlock);
		world.setBlock(i + 24, j + 4, k + 11, selectedBlock);
		world.setBlock(i + 24, j + 4, k + 12, selectedBlock);
		world.setBlock(i + 24, j + 4, k + 13, selectedBlock);
		world.setBlock(i + 24, j + 4, k + 14, selectedBlock);
		world.setBlock(i + 24, j + 4, k + 15, selectedBlock);
		world.setBlock(i + 24, j + 4, k + 16, selectedBlock);
		world.setBlock(i + 24, j + 5, k + 10, selectedBlock);
		world.setBlock(i + 24, j + 5, k + 11, selectedBlock);
		world.setBlock(i + 24, j + 5, k + 12, selectedBlock);
		world.setBlock(i + 24, j + 5, k + 13, selectedBlock);
		world.setBlock(i + 24, j + 5, k + 14, selectedBlock);
		world.setBlock(i + 24, j + 5, k + 15, selectedBlock);
		world.setBlock(i + 24, j + 5, k + 16, selectedBlock);
		world.setBlock(i + 24, j + 6, k + 10, selectedBlock);
		world.setBlock(i + 24, j + 6, k + 11, selectedBlock);
		world.setBlock(i + 24, j + 6, k + 12, selectedBlock);
		world.setBlock(i + 24, j + 6, k + 13, selectedBlock);
		world.setBlock(i + 24, j + 6, k + 14, selectedBlock);
		world.setBlock(i + 24, j + 6, k + 15, selectedBlock);
		world.setBlock(i + 24, j + 6, k + 16, selectedBlock);
		world.setBlock(i + 24, j + 7, k + 10, selectedBlock);
		world.setBlock(i + 24, j + 7, k + 11, selectedBlock);
		world.setBlock(i + 24, j + 7, k + 12, selectedBlock);
		world.setBlock(i + 24, j + 7, k + 13, selectedBlock);
		world.setBlock(i + 24, j + 7, k + 14, selectedBlock);
		world.setBlock(i + 24, j + 7, k + 15, selectedBlock);
		world.setBlock(i + 24, j + 7, k + 16, selectedBlock);
		world.setBlock(i + 24, j + 8, k + 10, selectedBlock);
		world.setBlock(i + 24, j + 8, k + 11, selectedBlock);
		world.setBlock(i + 24, j + 8, k + 12, selectedBlock);
		world.setBlock(i + 24, j + 8, k + 13, selectedBlock);
		world.setBlock(i + 24, j + 8, k + 14, selectedBlock);
		world.setBlock(i + 24, j + 8, k + 15, selectedBlock);
		world.setBlock(i + 24, j + 8, k + 16, selectedBlock);
		return true;
	}
}