package idim.dims.testdim.worldgen.village;

import idim.blocks.Blocks;
import idim.methods.Methods;

import java.util.Random;

import net.minecraft.block.Block;
import net.minecraft.world.World;
import net.minecraft.world.gen.feature.WorldGenerator;

public class VillageHouseOne extends WorldGenerator
{
	protected int[] GetValidSpawnBlocks() {
		return new int[] { Blocks.purpleSand.blockID,
				Blocks.creepStone.blockID, Blocks.creepDirt.blockID,
				Blocks.purpleCaveStone.blockID, Blocks.purpleCobble.blockID };
	}
	
	public boolean LocationIsValidSpawn(World world, int i, int j, int k) {
		int distanceToAir = 0;
		int checkID = world.getBlockId(i, j, k);
		
		while (checkID != 0) {
			distanceToAir++;
			checkID = world.getBlockId(i, j + distanceToAir, k);
		}
		
		if (distanceToAir > 3) {
			return false;
		}
		j += distanceToAir - 1;
		
		int blockID = world.getBlockId(i, j, k);
		int blockIDAbove = world.getBlockId(i, j + 1, k);
		int blockIDBelow = world.getBlockId(i, j - 1, k);
		for (int x : GetValidSpawnBlocks()) {
			if (blockIDAbove != 0) {
				return false;
			}
			if (blockID == x) {
				return true;
			} else if (blockID == Blocks.purpleCaveStone.blockID
					&& blockIDBelow == x) {
				return true;
			}
		}
		return false;
	}
	
	public VillageHouseOne() {
	}
	
	@Override
	public boolean generate(World world, Random rand, int i, int j, int k) {
		Methods.echo("Attempting to spawn village house one..");
		if (!LocationIsValidSpawn(world, i, j, k)) {
			Methods.echo("Failed");
			return false;
		}
		world.setBlock(i + 0, j + 0, k + 0, Blocks.purpleSand.blockID);
		world.setBlock(i + 0, j + 0, k + 1, Blocks.purpleSand.blockID);
		world.setBlock(i + 0, j + 0, k + 2, Blocks.purpleSand.blockID);
		world.setBlock(i + 0, j + 0, k + 3, Blocks.purpleSand.blockID);
		world.setBlock(i + 0, j + 0, k + 4, Blocks.purpleSand.blockID);
		world.setBlock(i + 0, j + 0, k + 5, Blocks.purpleSand.blockID);
		world.setBlock(i + 0, j + 0, k + 6, Blocks.purpleSand.blockID);
		world.setBlock(i + 0, j + 0, k + 7, Blocks.purpleSand.blockID);
		world.setBlock(i + 0, j + 0, k + 8, Blocks.purpleSand.blockID);
		world.setBlock(i + 0, j + 0, k + 9, Blocks.purpleSand.blockID);
		world.setBlock(i + 0, j + 0, k + 10, Blocks.purpleSand.blockID);
		world.setBlock(i + 0, j + 0, k + 11, Blocks.purpleSand.blockID);
		world.setBlock(i + 0, j + 0, k + 12, Blocks.purpleSand.blockID);
		world.setBlock(i + 0, j + 0, k + 13, Blocks.purpleSand.blockID);
		world.setBlock(i + 0, j + 0, k + 14, Blocks.purpleSand.blockID);
		world.setBlock(i + 0, j + 0, k + 15, Blocks.purpleSand.blockID);
		world.setBlock(i + 0, j + 0, k + 16, Blocks.purpleSand.blockID);
		world.setBlock(i + 0, j + 0, k + 17, Blocks.purpleSand.blockID);
		world.setBlock(i + 0, j + 0, k + 18, Blocks.purpleSand.blockID);
		world.setBlock(i + 0, j + 0, k + 19, Blocks.purpleSand.blockID);
		world.setBlock(i + 0, j + 0, k + 20, Blocks.purpleSand.blockID);
		world.setBlock(i + 0, j + 0, k + 21, Blocks.purpleSand.blockID);
		world.setBlock(i + 0, j + 0, k + 22, Blocks.purpleSand.blockID);
		world.setBlock(i + 0, j + 0, k + 23, Blocks.purpleSand.blockID);
		world.setBlock(i + 1, j + 0, k + 0, Blocks.purpleSand.blockID);
		world.setBlock(i + 1, j + 0, k + 1, Blocks.purpleSand.blockID);
		world.setBlock(i + 1, j + 0, k + 2, Blocks.purpleSand.blockID);
		world.setBlock(i + 1, j + 0, k + 3, Blocks.purpleSand.blockID);
		world.setBlock(i + 1, j + 0, k + 4, Blocks.purpleSand.blockID);
		world.setBlock(i + 1, j + 0, k + 5, Blocks.purpleSand.blockID);
		world.setBlock(i + 1, j + 0, k + 6, Blocks.purpleSand.blockID);
		world.setBlock(i + 1, j + 0, k + 7, Blocks.purpleSand.blockID);
		world.setBlock(i + 1, j + 0, k + 8, Blocks.purpleSand.blockID);
		world.setBlock(i + 1, j + 0, k + 9, Blocks.purpleSand.blockID);
		world.setBlock(i + 1, j + 0, k + 10, Blocks.purpleSand.blockID);
		world.setBlock(i + 1, j + 0, k + 11, Blocks.purpleSand.blockID);
		world.setBlock(i + 1, j + 0, k + 12, Blocks.purpleSand.blockID);
		world.setBlock(i + 1, j + 0, k + 13, Blocks.purpleSand.blockID);
		world.setBlock(i + 1, j + 0, k + 14, Blocks.purpleSand.blockID);
		world.setBlock(i + 1, j + 0, k + 15, Blocks.purpleSand.blockID);
		world.setBlock(i + 1, j + 0, k + 16, Blocks.purpleSand.blockID);
		world.setBlock(i + 1, j + 0, k + 17, Blocks.purpleSand.blockID);
		world.setBlock(i + 1, j + 0, k + 18, Blocks.purpleSand.blockID);
		world.setBlock(i + 1, j + 0, k + 19, Blocks.purpleSand.blockID);
		world.setBlock(i + 1, j + 0, k + 20, Blocks.purpleSand.blockID);
		world.setBlock(i + 1, j + 0, k + 21, Blocks.purpleSand.blockID);
		world.setBlock(i + 1, j + 0, k + 22, Blocks.purpleSand.blockID);
		world.setBlock(i + 1, j + 0, k + 23, Blocks.purpleSand.blockID);
		world.setBlock(i + 2, j + 0, k + 0, Blocks.purpleSand.blockID);
		world.setBlock(i + 2, j + 0, k + 1, Blocks.purpleSand.blockID);
		world.setBlock(i + 2, j + 0, k + 3, Blocks.purpleSand.blockID);
		world.setBlock(i + 2, j + 0, k + 5, Blocks.purpleSand.blockID);
		world.setBlock(i + 2, j + 0, k + 6, Blocks.purpleSand.blockID);
		world.setBlock(i + 2, j + 0, k + 7, Blocks.purpleSand.blockID);
		world.setBlock(i + 2, j + 0, k + 8, Blocks.purpleSand.blockID);
		world.setBlock(i + 2, j + 0, k + 9, Blocks.purpleSand.blockID);
		world.setBlock(i + 2, j + 0, k + 10, Blocks.purpleSand.blockID);
		world.setBlock(i + 2, j + 0, k + 11, Blocks.purpleSand.blockID);
		world.setBlock(i + 2, j + 0, k + 12, Blocks.purpleSand.blockID);
		world.setBlock(i + 2, j + 0, k + 13, Blocks.purpleSand.blockID);
		world.setBlock(i + 2, j + 0, k + 14, Blocks.purpleSand.blockID);
		world.setBlock(i + 2, j + 0, k + 15, Blocks.purpleSand.blockID);
		world.setBlock(i + 2, j + 0, k + 16, Blocks.purpleSand.blockID);
		world.setBlock(i + 2, j + 0, k + 17, Blocks.purpleSand.blockID);
		world.setBlock(i + 2, j + 0, k + 18, Blocks.purpleSand.blockID);
		world.setBlock(i + 2, j + 0, k + 19, Blocks.purpleSand.blockID);
		world.setBlock(i + 2, j + 0, k + 20, Blocks.purpleSand.blockID);
		world.setBlock(i + 2, j + 0, k + 21, Blocks.purpleSand.blockID);
		world.setBlock(i + 2, j + 0, k + 22, Blocks.purpleSand.blockID);
		world.setBlock(i + 2, j + 0, k + 23, Blocks.purpleSand.blockID);
		world.setBlock(i + 2, j + 0, k + 24, Blocks.purpleSand.blockID);
		world.setBlock(i + 3, j + 0, k + 0, Blocks.purpleSand.blockID);
		world.setBlock(i + 3, j + 0, k + 1, Blocks.purpleSand.blockID);
		world.setBlock(i + 3, j + 0, k + 2, Blocks.purpleSand.blockID);
		world.setBlock(i + 3, j + 0, k + 3, Blocks.purpleSand.blockID);
		world.setBlock(i + 3, j + 0, k + 4, Blocks.purpleSand.blockID);
		world.setBlock(i + 3, j + 0, k + 5, Blocks.purpleSand.blockID);
		world.setBlock(i + 3, j + 0, k + 6, Blocks.purpleSand.blockID);
		world.setBlock(i + 3, j + 0, k + 7, Blocks.purpleSand.blockID);
		world.setBlock(i + 3, j + 0, k + 8, Blocks.purpleSand.blockID);
		world.setBlock(i + 3, j + 0, k + 9, Blocks.purpleSand.blockID);
		world.setBlock(i + 3, j + 0, k + 10, Blocks.purpleSand.blockID);
		world.setBlock(i + 3, j + 0, k + 11, Blocks.purpleSand.blockID);
		world.setBlock(i + 3, j + 0, k + 12, Blocks.purpleSand.blockID);
		world.setBlock(i + 3, j + 0, k + 13, Blocks.purpleSand.blockID);
		world.setBlock(i + 3, j + 0, k + 14, Blocks.purpleSand.blockID);
		world.setBlock(i + 3, j + 0, k + 15, Blocks.purpleSand.blockID);
		world.setBlock(i + 3, j + 0, k + 16, Blocks.purpleSand.blockID);
		world.setBlock(i + 3, j + 0, k + 17, Blocks.purpleSand.blockID);
		world.setBlock(i + 3, j + 0, k + 18, Blocks.purpleSand.blockID);
		world.setBlock(i + 3, j + 0, k + 19, Blocks.purpleSand.blockID);
		world.setBlock(i + 3, j + 0, k + 20, Blocks.purpleSand.blockID);
		world.setBlock(i + 3, j + 0, k + 21, Blocks.purpleSand.blockID);
		world.setBlock(i + 3, j + 0, k + 22, Blocks.purpleSand.blockID);
		world.setBlock(i + 3, j + 0, k + 23, Blocks.purpleSand.blockID);
		world.setBlock(i + 3, j + 0, k + 24, Blocks.purpleSand.blockID);
		world.setBlock(i + 4, j + 0, k + 0, Blocks.purpleSand.blockID);
		world.setBlock(i + 4, j + 0, k + 1, Blocks.purpleSand.blockID);
		world.setBlock(i + 4, j + 0, k + 2, Blocks.purpleSand.blockID);
		world.setBlock(i + 4, j + 0, k + 3, Blocks.purpleSand.blockID);
		world.setBlock(i + 4, j + 0, k + 4, Blocks.purpleSand.blockID);
		world.setBlock(i + 4, j + 0, k + 5, Blocks.purpleSand.blockID);
		world.setBlock(i + 4, j + 0, k + 6, Blocks.purpleSand.blockID);
		world.setBlock(i + 4, j + 0, k + 7, Blocks.purpleSand.blockID);
		world.setBlock(i + 4, j + 0, k + 8, Blocks.purpleSand.blockID);
		world.setBlock(i + 4, j + 0, k + 9, Blocks.purpleSand.blockID);
		world.setBlock(i + 4, j + 0, k + 10, Blocks.purpleSand.blockID);
		world.setBlock(i + 4, j + 0, k + 11, Blocks.purpleSand.blockID);
		world.setBlock(i + 4, j + 0, k + 12, Blocks.purpleSand.blockID);
		world.setBlock(i + 4, j + 0, k + 13, Blocks.purpleSand.blockID);
		world.setBlock(i + 4, j + 0, k + 14, Blocks.purpleSand.blockID);
		world.setBlock(i + 4, j + 0, k + 15, Blocks.purpleSand.blockID);
		world.setBlock(i + 4, j + 0, k + 16, Blocks.purpleSand.blockID);
		world.setBlock(i + 4, j + 0, k + 17, Blocks.purpleSand.blockID);
		world.setBlock(i + 4, j + 0, k + 18, Blocks.purpleSand.blockID);
		world.setBlock(i + 4, j + 0, k + 19, Blocks.purpleSand.blockID);
		world.setBlock(i + 4, j + 0, k + 20, Blocks.purpleSand.blockID);
		world.setBlock(i + 4, j + 0, k + 21, Blocks.purpleSand.blockID);
		world.setBlock(i + 4, j + 0, k + 22, Blocks.purpleSand.blockID);
		world.setBlock(i + 4, j + 0, k + 23, Blocks.purpleSand.blockID);
		world.setBlock(i + 4, j + 0, k + 24, Blocks.purpleSand.blockID);
		world.setBlock(i + 5, j + 0, k + 0, Blocks.purpleSand.blockID);
		world.setBlock(i + 5, j + 0, k + 1, Blocks.purpleSand.blockID);
		world.setBlock(i + 5, j + 0, k + 2, Blocks.purpleSand.blockID);
		world.setBlock(i + 5, j + 0, k + 3, Blocks.purpleSand.blockID);
		world.setBlock(i + 5, j + 0, k + 4, Blocks.purpleSand.blockID);
		world.setBlock(i + 5, j + 0, k + 5, Blocks.purpleSand.blockID);
		world.setBlock(i + 5, j + 0, k + 6, Blocks.purpleSand.blockID);
		world.setBlock(i + 5, j + 0, k + 7, Blocks.purpleSand.blockID);
		world.setBlock(i + 5, j + 0, k + 17, Blocks.purpleSand.blockID);
		world.setBlock(i + 5, j + 0, k + 18, Blocks.purpleSand.blockID);
		world.setBlock(i + 5, j + 0, k + 19, Blocks.purpleSand.blockID);
		world.setBlock(i + 5, j + 0, k + 20, Blocks.purpleSand.blockID);
		world.setBlock(i + 5, j + 0, k + 21, Blocks.purpleSand.blockID);
		world.setBlock(i + 5, j + 0, k + 22, Blocks.purpleSand.blockID);
		world.setBlock(i + 5, j + 0, k + 23, Blocks.purpleSand.blockID);
		world.setBlock(i + 5, j + 0, k + 24, Blocks.purpleSand.blockID);
		
		world.setBlock(i + 5, j + 1, k + 8, Blocks.purpleCobble.blockID);
		world.setBlock(i + 5, j + 1, k + 9, Blocks.purpleCobble.blockID);
		world.setBlock(i + 5, j + 1, k + 10, Blocks.purpleCobble.blockID);
		world.setBlock(i + 5, j + 1, k + 11, Blocks.purpleCobble.blockID);
		world.setBlock(i + 5, j + 1, k + 12, Blocks.purpleCobble.blockID);
		world.setBlock(i + 5, j + 1, k + 13, Blocks.purpleCobble.blockID);
		world.setBlock(i + 5, j + 1, k + 14, Blocks.purpleCobble.blockID);
		world.setBlock(i + 5, j + 1, k + 15, Blocks.purpleCobble.blockID);
		world.setBlock(i + 5, j + 1, k + 16, Blocks.purpleCobble.blockID);
		world.setBlock(i + 5, j + 2, k + 8, Blocks.purpleCobble.blockID);
		world.setBlock(i + 5, j + 2, k + 9, Blocks.purpleCobble.blockID);
		world.setBlock(i + 5, j + 2, k + 10, Blocks.purpleCobble.blockID);
		world.setBlock(i + 5, j + 2, k + 11, Blocks.purpleCobble.blockID);
		world.setBlock(i + 5, j + 2, k + 12, Blocks.purpleCobble.blockID);
		world.setBlock(i + 5, j + 2, k + 13, Blocks.purpleCobble.blockID);
		world.setBlock(i + 5, j + 2, k + 14, Blocks.purpleCobble.blockID);
		world.setBlock(i + 5, j + 2, k + 15, Blocks.purpleCobble.blockID);
		world.setBlock(i + 5, j + 2, k + 16, Blocks.purpleCobble.blockID);
		world.setBlock(i + 5, j + 3, k + 8, Blocks.purpleCobble.blockID);
		world.setBlock(i + 5, j + 3, k + 9, Blocks.palmPlanks.blockID);
		world.setBlock(i + 5, j + 3, k + 10, Blocks.purpleGlass.blockID);
		world.setBlock(i + 5, j + 3, k + 11, Blocks.purpleGlass.blockID);
		world.setBlock(i + 5, j + 3, k + 12, Blocks.palmPlanks.blockID);
		world.setBlock(i + 5, j + 3, k + 13, Blocks.purpleGlass.blockID);
		world.setBlock(i + 5, j + 3, k + 14, Blocks.purpleGlass.blockID);
		world.setBlock(i + 5, j + 3, k + 15, Blocks.palmPlanks.blockID);
		world.setBlock(i + 5, j + 3, k + 16, Blocks.purpleCobble.blockID);
		world.setBlock(i + 5, j + 4, k + 8, Blocks.purpleCobble.blockID);
		world.setBlock(i + 5, j + 4, k + 9, Blocks.palmPlanks.blockID);
		world.setBlock(i + 5, j + 4, k + 10, Blocks.palmPlanks.blockID);
		world.setBlock(i + 5, j + 4, k + 11, Blocks.palmPlanks.blockID);
		world.setBlock(i + 5, j + 4, k + 12, Blocks.palmPlanks.blockID);
		world.setBlock(i + 5, j + 4, k + 13, Blocks.palmPlanks.blockID);
		world.setBlock(i + 5, j + 4, k + 14, Blocks.palmPlanks.blockID);
		world.setBlock(i + 5, j + 4, k + 15, Blocks.palmPlanks.blockID);
		world.setBlock(i + 5, j + 4, k + 16, Blocks.purpleCobble.blockID);
		world.setBlock(i + 5, j + 5, k + 8, Blocks.purpleCobble.blockID);
		world.setBlock(i + 5, j + 5, k + 9, Blocks.palmPlanks.blockID);
		world.setBlock(i + 5, j + 5, k + 10, Blocks.palmPlanks.blockID);
		world.setBlock(i + 5, j + 5, k + 11, Blocks.palmPlanks.blockID);
		world.setBlock(i + 5, j + 5, k + 12, Blocks.palmPlanks.blockID);
		world.setBlock(i + 5, j + 5, k + 13, Blocks.palmPlanks.blockID);
		world.setBlock(i + 5, j + 5, k + 14, Blocks.palmPlanks.blockID);
		world.setBlock(i + 5, j + 5, k + 15, Blocks.palmPlanks.blockID);
		world.setBlock(i + 5, j + 5, k + 16, Blocks.purpleCobble.blockID);
		world.setBlock(i + 5, j + 6, k + 8, Blocks.purpleCobble.blockID);
		world.setBlock(i + 5, j + 6, k + 9, Blocks.purpleCobble.blockID);
		world.setBlock(i + 5, j + 6, k + 10, Blocks.purpleCobble.blockID);
		world.setBlock(i + 5, j + 6, k + 11, Blocks.purpleCobble.blockID);
		world.setBlock(i + 5, j + 6, k + 12, Blocks.purpleCobble.blockID);
		world.setBlock(i + 5, j + 6, k + 13, Blocks.purpleCobble.blockID);
		world.setBlock(i + 5, j + 6, k + 14, Blocks.purpleCobble.blockID);
		world.setBlock(i + 5, j + 6, k + 15, Blocks.purpleCobble.blockID);
		world.setBlock(i + 5, j + 6, k + 16, Blocks.purpleCobble.blockID);
		
		world.setBlock(i + 6, j + 0, k + 0, Blocks.purpleSand.blockID);
		world.setBlock(i + 6, j + 0, k + 1, Blocks.purpleSand.blockID);
		world.setBlock(i + 6, j + 0, k + 2, Blocks.purpleSand.blockID);
		world.setBlock(i + 6, j + 0, k + 3, Blocks.purpleSand.blockID);
		world.setBlock(i + 6, j + 0, k + 4, Blocks.purpleSand.blockID);
		world.setBlock(i + 6, j + 0, k + 5, Blocks.purpleSand.blockID);
		world.setBlock(i + 6, j + 0, k + 6, Blocks.purpleSand.blockID);
		world.setBlock(i + 6, j + 0, k + 7, Blocks.purpleSand.blockID);
		world.setBlock(i + 6, j + 0, k + 17, Blocks.purpleSand.blockID);
		world.setBlock(i + 6, j + 0, k + 18, Blocks.purpleSand.blockID);
		world.setBlock(i + 6, j + 0, k + 19, Blocks.purpleSand.blockID);
		world.setBlock(i + 6, j + 0, k + 20, Blocks.purpleSand.blockID);
		world.setBlock(i + 6, j + 0, k + 21, Blocks.purpleSand.blockID);
		world.setBlock(i + 6, j + 0, k + 22, Blocks.purpleSand.blockID);
		world.setBlock(i + 6, j + 0, k + 23, Blocks.purpleSand.blockID);
		world.setBlock(i + 6, j + 0, k + 24, Blocks.purpleSand.blockID);
		
		world.setBlock(i + 6, j + 1, k + 8, Blocks.purpleCobble.blockID);
		world.setBlock(i + 6, j + 1, k + 9, Blocks.purpleCobble.blockID);
		world.setBlock(i + 6, j + 1, k + 10, Blocks.purpleCobble.blockID);
		world.setBlock(i + 6, j + 1, k + 11, Blocks.purpleCobble.blockID);
		world.setBlock(i + 6, j + 1, k + 12, Blocks.purpleCobble.blockID);
		world.setBlock(i + 6, j + 1, k + 13, Blocks.purpleCobble.blockID);
		world.setBlock(i + 6, j + 1, k + 14, Blocks.purpleCobble.blockID);
		world.setBlock(i + 6, j + 1, k + 15, Blocks.purpleCobble.blockID);
		world.setBlock(i + 6, j + 1, k + 16, Blocks.purpleCobble.blockID);
		world.setBlock(i + 6, j + 2, k + 8, Blocks.purpleCobble.blockID);
		world.setBlock(i + 6, j + 2, k + 15, Blocks.palmPlanks.blockID);
		world.setBlock(i + 6, j + 2, k + 16, Blocks.purpleCobble.blockID);
		world.setBlock(i + 6, j + 3, k + 8, Blocks.palmPlanks.blockID);
		world.setBlock(i + 6, j + 3, k + 16, Blocks.palmPlanks.blockID);
		world.setBlock(i + 6, j + 4, k + 8, Blocks.palmPlanks.blockID);
		world.setBlock(i + 6, j + 4, k + 9, Block.bookShelf.blockID);
		world.setBlock(i + 6, j + 4, k + 10, Block.bookShelf.blockID);
		world.setBlock(i + 6, j + 4, k + 11, Block.bookShelf.blockID);
		world.setBlock(i + 6, j + 4, k + 12, Block.bookShelf.blockID);
		world.setBlock(i + 6, j + 4, k + 13, Block.bookShelf.blockID);
		world.setBlock(i + 6, j + 4, k + 14, Block.bookShelf.blockID);
		world.setBlock(i + 6, j + 4, k + 15, Block.bookShelf.blockID);
		world.setBlock(i + 6, j + 4, k + 16, Blocks.palmPlanks.blockID);
		world.setBlock(i + 6, j + 5, k + 8, Blocks.palmPlanks.blockID);
		world.setBlock(i + 6, j + 5, k + 9, Blocks.palmPlanks.blockID);
		world.setBlock(i + 6, j + 5, k + 10, Blocks.palmPlanks.blockID);
		world.setBlock(i + 6, j + 5, k + 11, Blocks.palmPlanks.blockID);
		world.setBlock(i + 6, j + 5, k + 12, Blocks.palmPlanks.blockID);
		world.setBlock(i + 6, j + 5, k + 13, Blocks.palmPlanks.blockID);
		world.setBlock(i + 6, j + 5, k + 14, Blocks.palmPlanks.blockID);
		world.setBlock(i + 6, j + 5, k + 15, Blocks.palmPlanks.blockID);
		world.setBlock(i + 6, j + 5, k + 16, Blocks.palmPlanks.blockID);
		world.setBlock(i + 6, j + 6, k + 8, Blocks.purpleCobble.blockID);
		world.setBlock(i + 6, j + 6, k + 9, Blocks.purpleCobble.blockID);
		world.setBlock(i + 6, j + 6, k + 10, Blocks.purpleCobble.blockID);
		world.setBlock(i + 6, j + 6, k + 11, Blocks.purpleCobble.blockID);
		world.setBlock(i + 6, j + 6, k + 12, Blocks.purpleCobble.blockID);
		world.setBlock(i + 6, j + 6, k + 13, Blocks.purpleCobble.blockID);
		world.setBlock(i + 6, j + 6, k + 14, Blocks.purpleCobble.blockID);
		world.setBlock(i + 6, j + 6, k + 15, Blocks.purpleCobble.blockID);
		world.setBlock(i + 6, j + 6, k + 16, Blocks.purpleCobble.blockID);
		world.setBlock(i + 6, j + 7, k + 8, Blocks.purpleCobble.blockID);
		world.setBlock(i + 6, j + 7, k + 9, Blocks.purpleCobble.blockID);
		world.setBlock(i + 6, j + 7, k + 10, Blocks.purpleCobble.blockID);
		world.setBlock(i + 6, j + 7, k + 11, Blocks.purpleCobble.blockID);
		world.setBlock(i + 6, j + 7, k + 12, Blocks.purpleCobble.blockID);
		world.setBlock(i + 6, j + 7, k + 13, Blocks.purpleCobble.blockID);
		world.setBlock(i + 6, j + 7, k + 14, Blocks.purpleCobble.blockID);
		world.setBlock(i + 6, j + 7, k + 15, Blocks.purpleCobble.blockID);
		world.setBlock(i + 6, j + 7, k + 16, Blocks.purpleCobble.blockID);
		
		world.setBlock(i + 7, j + 0, k + 0, Blocks.purpleSand.blockID);
		world.setBlock(i + 7, j + 0, k + 1, Blocks.purpleSand.blockID);
		world.setBlock(i + 7, j + 0, k + 2, Blocks.purpleSand.blockID);
		world.setBlock(i + 7, j + 0, k + 3, Blocks.purpleSand.blockID);
		world.setBlock(i + 7, j + 0, k + 4, Blocks.purpleSand.blockID);
		world.setBlock(i + 7, j + 0, k + 5, Blocks.purpleSand.blockID);
		world.setBlock(i + 7, j + 0, k + 6, Blocks.purpleSand.blockID);
		world.setBlock(i + 7, j + 0, k + 7, Blocks.purpleSand.blockID);
		world.setBlock(i + 7, j + 0, k + 17, Blocks.purpleSand.blockID);
		world.setBlock(i + 7, j + 0, k + 18, Blocks.purpleSand.blockID);
		world.setBlock(i + 7, j + 0, k + 19, Blocks.purpleSand.blockID);
		world.setBlock(i + 7, j + 0, k + 20, Blocks.purpleSand.blockID);
		world.setBlock(i + 7, j + 0, k + 21, Blocks.purpleSand.blockID);
		world.setBlock(i + 7, j + 0, k + 22, Blocks.purpleSand.blockID);
		world.setBlock(i + 7, j + 0, k + 23, Blocks.purpleSand.blockID);
		world.setBlock(i + 7, j + 0, k + 24, Blocks.purpleSand.blockID);
		
		world.setBlock(i + 7, j + 1, k + 8, Blocks.purpleCobble.blockID);
		world.setBlock(i + 7, j + 1, k + 9, Blocks.purpleCobble.blockID);
		world.setBlock(i + 7, j + 1, k + 10, Blocks.purpleCobble.blockID);
		world.setBlock(i + 7, j + 1, k + 11, Blocks.purpleCobble.blockID);
		world.setBlock(i + 7, j + 1, k + 12, Blocks.purpleCobble.blockID);
		world.setBlock(i + 7, j + 1, k + 13, Blocks.purpleCobble.blockID);
		world.setBlock(i + 7, j + 1, k + 14, Blocks.purpleCobble.blockID);
		world.setBlock(i + 7, j + 1, k + 15, Blocks.purpleCobble.blockID);
		world.setBlock(i + 7, j + 1, k + 16, Blocks.purpleCobble.blockID);
		world.setBlock(i + 7, j + 2, k + 8, Blocks.purpleCobble.blockID);
		world.setBlock(i + 7, j + 2, k + 16, Blocks.purpleCobble.blockID);
		world.setBlock(i + 7, j + 3, k + 8, Blocks.purpleGlass.blockID);
		world.setBlock(i + 7, j + 3, k + 16, Blocks.purpleGlass.blockID);
		world.setBlock(i + 7, j + 4, k + 8, Blocks.purpleGlass.blockID);
		world.setBlock(i + 7, j + 4, k + 16, Blocks.purpleGlass.blockID);
		world.setBlock(i + 7, j + 5, k + 8, Blocks.palmPlanks.blockID);
		world.setBlock(i + 7, j + 5, k + 16, Blocks.palmPlanks.blockID);
		world.setBlock(i + 7, j + 6, k + 8, Blocks.purpleCobble.blockID);
		world.setBlock(i + 7, j + 6, k + 9, Blocks.purpleCobble.blockID);
		world.setBlock(i + 7, j + 6, k + 10, Blocks.purpleCobble.blockID);
		world.setBlock(i + 7, j + 6, k + 11, Blocks.purpleCobble.blockID);
		world.setBlock(i + 7, j + 6, k + 12, Blocks.purpleCobble.blockID);
		world.setBlock(i + 7, j + 6, k + 13, Blocks.purpleCobble.blockID);
		world.setBlock(i + 7, j + 6, k + 14, Blocks.purpleCobble.blockID);
		world.setBlock(i + 7, j + 6, k + 15, Blocks.purpleCobble.blockID);
		world.setBlock(i + 7, j + 6, k + 16, Blocks.purpleCobble.blockID);
		world.setBlock(i + 7, j + 7, k + 8, Blocks.purpleCobble.blockID);
		world.setBlock(i + 7, j + 7, k + 9, Blocks.purpleCobble.blockID);
		world.setBlock(i + 7, j + 7, k + 10, Blocks.purpleCobble.blockID);
		world.setBlock(i + 7, j + 7, k + 11, Blocks.purpleCobble.blockID);
		world.setBlock(i + 7, j + 7, k + 12, Blocks.purpleCobble.blockID);
		world.setBlock(i + 7, j + 7, k + 13, Blocks.purpleCobble.blockID);
		world.setBlock(i + 7, j + 7, k + 14, Blocks.purpleCobble.blockID);
		world.setBlock(i + 7, j + 7, k + 15, Blocks.purpleCobble.blockID);
		world.setBlock(i + 7, j + 7, k + 16, Blocks.purpleCobble.blockID);
		world.setBlock(i + 7, j + 8, k + 8, Blocks.purpleCobble.blockID);
		world.setBlock(i + 7, j + 8, k + 9, Blocks.purpleCobble.blockID);
		world.setBlock(i + 7, j + 8, k + 10, Blocks.purpleCobble.blockID);
		world.setBlock(i + 7, j + 8, k + 11, Blocks.purpleCobble.blockID);
		world.setBlock(i + 7, j + 8, k + 12, Blocks.purpleCobble.blockID);
		world.setBlock(i + 7, j + 8, k + 13, Blocks.purpleCobble.blockID);
		world.setBlock(i + 7, j + 8, k + 14, Blocks.purpleCobble.blockID);
		world.setBlock(i + 7, j + 8, k + 15, Blocks.purpleCobble.blockID);
		world.setBlock(i + 7, j + 8, k + 16, Blocks.purpleSand.blockID);
		
		world.setBlock(i + 8, j + 0, k + 0, Blocks.purpleSand.blockID);
		world.setBlock(i + 8, j + 0, k + 1, Blocks.purpleSand.blockID);
		world.setBlock(i + 8, j + 0, k + 2, Blocks.purpleSand.blockID);
		world.setBlock(i + 8, j + 0, k + 3, Blocks.purpleSand.blockID);
		world.setBlock(i + 8, j + 0, k + 4, Blocks.purpleSand.blockID);
		world.setBlock(i + 8, j + 0, k + 5, Blocks.purpleSand.blockID);
		world.setBlock(i + 8, j + 0, k + 6, Blocks.purpleSand.blockID);
		world.setBlock(i + 8, j + 0, k + 7, Blocks.purpleSand.blockID);
		world.setBlock(i + 8, j + 0, k + 17, Blocks.purpleSand.blockID);
		world.setBlock(i + 8, j + 0, k + 18, Blocks.purpleSand.blockID);
		world.setBlock(i + 8, j + 0, k + 19, Blocks.purpleSand.blockID);
		world.setBlock(i + 8, j + 0, k + 20, Blocks.purpleSand.blockID);
		world.setBlock(i + 8, j + 0, k + 21, Blocks.purpleSand.blockID);
		world.setBlock(i + 8, j + 0, k + 22, Blocks.purpleSand.blockID);
		world.setBlock(i + 8, j + 0, k + 23, Blocks.purpleSand.blockID);
		world.setBlock(i + 8, j + 0, k + 24, Blocks.purpleSand.blockID);
		
		world.setBlock(i + 8, j + 1, k + 8, Blocks.purpleCobble.blockID);
		world.setBlock(i + 8, j + 1, k + 9, Blocks.purpleCobble.blockID);
		world.setBlock(i + 8, j + 1, k + 10, Blocks.purpleCobble.blockID);
		world.setBlock(i + 8, j + 1, k + 11, Blocks.purpleCobble.blockID);
		world.setBlock(i + 8, j + 1, k + 12, Blocks.purpleCobble.blockID);
		world.setBlock(i + 8, j + 1, k + 13, Blocks.purpleCobble.blockID);
		world.setBlock(i + 8, j + 1, k + 14, Blocks.purpleCobble.blockID);
		world.setBlock(i + 8, j + 1, k + 15, Blocks.purpleCobble.blockID);
		world.setBlock(i + 8, j + 1, k + 16, Blocks.purpleCobble.blockID);
		world.setBlock(i + 8, j + 2, k + 8, Blocks.purpleCobble.blockID);
		world.setBlock(i + 8, j + 2, k + 16, Blocks.purpleCobble.blockID);
		world.setBlock(i + 8, j + 3, k + 8, Blocks.purpleGlass.blockID);
		world.setBlock(i + 8, j + 3, k + 16, Blocks.purpleGlass.blockID);
		world.setBlock(i + 8, j + 4, k + 8, Blocks.purpleGlass.blockID);
		world.setBlock(i + 8, j + 4, k + 16, Blocks.purpleGlass.blockID);
		world.setBlock(i + 8, j + 5, k + 8, Blocks.palmPlanks.blockID);
		world.setBlock(i + 8, j + 5, k + 16, Blocks.palmPlanks.blockID);
		world.setBlock(i + 8, j + 6, k + 8, Blocks.purpleCobble.blockID);
		world.setBlock(i + 8, j + 6, k + 9, Blocks.purpleCobble.blockID);
		world.setBlock(i + 8, j + 6, k + 10, Blocks.purpleCobble.blockID);
		world.setBlock(i + 8, j + 6, k + 11, Blocks.purpleCobble.blockID);
		world.setBlock(i + 8, j + 6, k + 12, Blocks.purpleCobble.blockID);
		world.setBlock(i + 8, j + 6, k + 13, Blocks.purpleCobble.blockID);
		world.setBlock(i + 8, j + 6, k + 14, Blocks.purpleCobble.blockID);
		world.setBlock(i + 8, j + 6, k + 15, Blocks.purpleCobble.blockID);
		world.setBlock(i + 8, j + 6, k + 16, Blocks.purpleCobble.blockID);
		world.setBlock(i + 8, j + 7, k + 8, Blocks.purpleCobble.blockID);
		world.setBlock(i + 8, j + 7, k + 9, Blocks.purpleCobble.blockID);
		world.setBlock(i + 8, j + 7, k + 10, Blocks.purpleCobble.blockID);
		world.setBlock(i + 8, j + 7, k + 11, Blocks.purpleCobble.blockID);
		world.setBlock(i + 8, j + 7, k + 12, Blocks.purpleCobble.blockID);
		world.setBlock(i + 8, j + 7, k + 13, Blocks.purpleCobble.blockID);
		world.setBlock(i + 8, j + 7, k + 14, Blocks.purpleCobble.blockID);
		world.setBlock(i + 8, j + 7, k + 15, Blocks.purpleCobble.blockID);
		world.setBlock(i + 8, j + 7, k + 16, Blocks.purpleCobble.blockID);
		world.setBlock(i + 8, j + 8, k + 8, Blocks.purpleCobble.blockID);
		world.setBlock(i + 8, j + 8, k + 9, Blocks.purpleCobble.blockID);
		world.setBlock(i + 8, j + 8, k + 10, Blocks.purpleCobble.blockID);
		world.setBlock(i + 8, j + 8, k + 11, Blocks.purpleCobble.blockID);
		world.setBlock(i + 8, j + 8, k + 12, Blocks.purpleCobble.blockID);
		world.setBlock(i + 8, j + 8, k + 13, Blocks.purpleCobble.blockID);
		world.setBlock(i + 8, j + 8, k + 14, Blocks.purpleCobble.blockID);
		world.setBlock(i + 8, j + 8, k + 15, Blocks.purpleCobble.blockID);
		world.setBlock(i + 8, j + 8, k + 16, Blocks.purpleSand.blockID);
		
		world.setBlock(i + 9, j + 0, k + 0, Blocks.purpleSand.blockID);
		world.setBlock(i + 9, j + 0, k + 1, Blocks.purpleSand.blockID);
		world.setBlock(i + 9, j + 0, k + 2, Blocks.purpleSand.blockID);
		world.setBlock(i + 9, j + 0, k + 3, Blocks.purpleSand.blockID);
		world.setBlock(i + 9, j + 0, k + 4, Blocks.purpleSand.blockID);
		world.setBlock(i + 9, j + 0, k + 5, Blocks.purpleSand.blockID);
		world.setBlock(i + 9, j + 0, k + 6, Blocks.purpleSand.blockID);
		world.setBlock(i + 9, j + 0, k + 7, Blocks.purpleSand.blockID);
		world.setBlock(i + 9, j + 0, k + 17, Blocks.purpleSand.blockID);
		world.setBlock(i + 9, j + 0, k + 18, Blocks.purpleSand.blockID);
		world.setBlock(i + 9, j + 0, k + 19, Blocks.purpleSand.blockID);
		world.setBlock(i + 9, j + 0, k + 20, Blocks.purpleSand.blockID);
		world.setBlock(i + 9, j + 0, k + 21, Blocks.purpleSand.blockID);
		world.setBlock(i + 9, j + 0, k + 22, Blocks.purpleSand.blockID);
		world.setBlock(i + 9, j + 0, k + 23, Blocks.purpleSand.blockID);
		world.setBlock(i + 9, j + 0, k + 24, Blocks.purpleSand.blockID);
		
		world.setBlock(i + 9, j + 1, k + 8, Blocks.purpleCobble.blockID);
		world.setBlock(i + 9, j + 1, k + 9, Blocks.purpleCobble.blockID);
		world.setBlock(i + 9, j + 1, k + 10, Blocks.purpleCobble.blockID);
		world.setBlock(i + 9, j + 1, k + 11, Blocks.purpleCobble.blockID);
		world.setBlock(i + 9, j + 1, k + 12, Blocks.purpleCobble.blockID);
		world.setBlock(i + 9, j + 1, k + 13, Blocks.purpleCobble.blockID);
		world.setBlock(i + 9, j + 1, k + 14, Blocks.purpleCobble.blockID);
		world.setBlock(i + 9, j + 1, k + 15, Blocks.purpleCobble.blockID);
		world.setBlock(i + 9, j + 1, k + 16, Blocks.purpleCobble.blockID);
		world.setBlock(i + 9, j + 2, k + 8, Blocks.purpleCobble.blockID);
		world.setBlock(i + 9, j + 2, k + 15, Block.workbench.blockID);
		WorldGenLostVillage.spawnVillager(world, i + 8, j + 3, k + 15, 1);
		world.setBlock(i + 9, j + 2, k + 16, Blocks.purpleCobble.blockID);
		world.setBlock(i + 9, j + 3, k + 8, Blocks.palmPlanks.blockID);
		world.setBlock(i + 9, j + 3, k + 16, Blocks.palmPlanks.blockID);
		world.setBlock(i + 9, j + 4, k + 8, Blocks.palmPlanks.blockID);
		world.setBlock(i + 9, j + 4, k + 16, Blocks.palmPlanks.blockID);
		world.setBlock(i + 9, j + 5, k + 8, Blocks.palmPlanks.blockID);
		world.setBlock(i + 9, j + 5, k + 9, Blocks.palmPlanks.blockID);
		world.setBlock(i + 9, j + 5, k + 10, Blocks.palmPlanks.blockID);
		world.setBlock(i + 9, j + 5, k + 11, Blocks.palmPlanks.blockID);
		world.setBlock(i + 9, j + 5, k + 12, Blocks.palmPlanks.blockID);
		world.setBlock(i + 9, j + 5, k + 13, Blocks.palmPlanks.blockID);
		world.setBlock(i + 9, j + 5, k + 14, Blocks.palmPlanks.blockID);
		world.setBlock(i + 9, j + 5, k + 15, Blocks.palmPlanks.blockID);
		world.setBlock(i + 9, j + 5, k + 16, Blocks.palmPlanks.blockID);
		world.setBlock(i + 9, j + 6, k + 8, Blocks.purpleCobble.blockID);
		world.setBlock(i + 9, j + 6, k + 9, Blocks.purpleCobble.blockID);
		world.setBlock(i + 9, j + 6, k + 10, Blocks.purpleCobble.blockID);
		world.setBlock(i + 9, j + 6, k + 11, Blocks.purpleCobble.blockID);
		world.setBlock(i + 9, j + 6, k + 12, Blocks.purpleCobble.blockID);
		world.setBlock(i + 9, j + 6, k + 13, Blocks.purpleCobble.blockID);
		world.setBlock(i + 9, j + 6, k + 14, Blocks.purpleCobble.blockID);
		world.setBlock(i + 9, j + 6, k + 15, Blocks.purpleCobble.blockID);
		world.setBlock(i + 9, j + 6, k + 16, Blocks.purpleCobble.blockID);
		world.setBlock(i + 9, j + 7, k + 8, Blocks.purpleCobble.blockID);
		world.setBlock(i + 9, j + 7, k + 9, Blocks.purpleCobble.blockID);
		world.setBlock(i + 9, j + 7, k + 10, Blocks.purpleCobble.blockID);
		world.setBlock(i + 9, j + 7, k + 11, Blocks.purpleCobble.blockID);
		world.setBlock(i + 9, j + 7, k + 12, Blocks.purpleCobble.blockID);
		world.setBlock(i + 9, j + 7, k + 13, Blocks.purpleCobble.blockID);
		world.setBlock(i + 9, j + 7, k + 14, Blocks.purpleCobble.blockID);
		world.setBlock(i + 9, j + 7, k + 15, Blocks.purpleCobble.blockID);
		world.setBlock(i + 9, j + 7, k + 16, Blocks.purpleCobble.blockID);
		
		world.setBlock(i + 10, j + 0, k + 0, Blocks.purpleSand.blockID);
		world.setBlock(i + 10, j + 0, k + 5, Blocks.purpleSand.blockID);
		world.setBlock(i + 10, j + 0, k + 6, Blocks.purpleSand.blockID);
		world.setBlock(i + 10, j + 0, k + 7, Blocks.purpleSand.blockID);
		world.setBlock(i + 10, j + 0, k + 17, Blocks.purpleSand.blockID);
		world.setBlock(i + 10, j + 0, k + 18, Blocks.purpleSand.blockID);
		world.setBlock(i + 10, j + 0, k + 19, Blocks.purpleSand.blockID);
		world.setBlock(i + 10, j + 0, k + 20, Blocks.purpleSand.blockID);
		world.setBlock(i + 10, j + 0, k + 21, Blocks.purpleSand.blockID);
		world.setBlock(i + 10, j + 0, k + 22, Blocks.purpleSand.blockID);
		world.setBlock(i + 10, j + 0, k + 23, Blocks.purpleSand.blockID);
		world.setBlock(i + 10, j + 0, k + 24, Blocks.purpleSand.blockID);
		
		world.setBlock(i + 10, j + 1, k + 8, Blocks.purpleCobble.blockID);
		world.setBlock(i + 10, j + 1, k + 9, Blocks.purpleCobble.blockID);
		world.setBlock(i + 10, j + 1, k + 10, Blocks.purpleCobble.blockID);
		world.setBlock(i + 10, j + 1, k + 11, Blocks.purpleCobble.blockID);
		world.setBlock(i + 10, j + 1, k + 12, Blocks.purpleCobble.blockID);
		world.setBlock(i + 10, j + 1, k + 13, Blocks.purpleCobble.blockID);
		world.setBlock(i + 10, j + 1, k + 14, Blocks.purpleCobble.blockID);
		world.setBlock(i + 10, j + 1, k + 15, Blocks.purpleCobble.blockID);
		world.setBlock(i + 10, j + 1, k + 16, Blocks.purpleCobble.blockID);
		world.setBlock(i + 10, j + 2, k + 8, Blocks.purpleCobble.blockID);
		world.setBlock(i + 10, j + 2, k + 10, Blocks.purpleCobble.blockID);
		world.setBlock(i + 10, j + 2, k + 11, Blocks.purpleCobble.blockID);
		world.setBlock(i + 10, j + 2, k + 12, Blocks.purpleCobble.blockID);
		world.setBlock(i + 10, j + 2, k + 13, Blocks.purpleCobble.blockID);
		world.setBlock(i + 10, j + 2, k + 14, Blocks.purpleCobble.blockID);
		world.setBlock(i + 10, j + 2, k + 15, Blocks.purpleCobble.blockID);
		world.setBlock(i + 10, j + 2, k + 16, Blocks.purpleCobble.blockID);
		world.setBlock(i + 10, j + 3, k + 8, Blocks.purpleCobble.blockID);
		world.setBlock(i + 10, j + 3, k + 10, Blocks.palmPlanks.blockID);
		world.setBlock(i + 10, j + 3, k + 11, Blocks.palmPlanks.blockID);
		world.setBlock(i + 10, j + 3, k + 12, Blocks.purpleGlass.blockID);
		world.setBlock(i + 10, j + 3, k + 13, Blocks.purpleGlass.blockID);
		world.setBlock(i + 10, j + 3, k + 14, Blocks.purpleGlass.blockID);
		world.setBlock(i + 10, j + 3, k + 15, Blocks.palmPlanks.blockID);
		world.setBlock(i + 10, j + 3, k + 16, Blocks.purpleCobble.blockID);
		world.setBlock(i + 10, j + 4, k + 8, Blocks.purpleCobble.blockID);
		world.setBlock(i + 10, j + 4, k + 9, Blocks.palmPlanks.blockID);
		world.setBlock(i + 10, j + 4, k + 10, Blocks.palmPlanks.blockID);
		world.setBlock(i + 10, j + 4, k + 11, Blocks.palmPlanks.blockID);
		world.setBlock(i + 10, j + 4, k + 12, Blocks.purpleGlass.blockID);
		world.setBlock(i + 10, j + 4, k + 13, Blocks.purpleGlass.blockID);
		world.setBlock(i + 10, j + 4, k + 14, Blocks.purpleGlass.blockID);
		world.setBlock(i + 10, j + 4, k + 15, Blocks.palmPlanks.blockID);
		world.setBlock(i + 10, j + 4, k + 16, Blocks.purpleCobble.blockID);
		world.setBlock(i + 10, j + 5, k + 8, Blocks.purpleCobble.blockID);
		world.setBlock(i + 10, j + 5, k + 9, Blocks.palmPlanks.blockID);
		world.setBlock(i + 10, j + 5, k + 10, Blocks.palmPlanks.blockID);
		world.setBlock(i + 10, j + 5, k + 11, Blocks.palmPlanks.blockID);
		world.setBlock(i + 10, j + 5, k + 12, Blocks.palmPlanks.blockID);
		world.setBlock(i + 10, j + 5, k + 13, Blocks.palmPlanks.blockID);
		world.setBlock(i + 10, j + 5, k + 14, Blocks.palmPlanks.blockID);
		world.setBlock(i + 10, j + 5, k + 15, Blocks.palmPlanks.blockID);
		world.setBlock(i + 10, j + 5, k + 16, Blocks.purpleCobble.blockID);
		world.setBlock(i + 10, j + 6, k + 8, Blocks.purpleCobble.blockID);
		world.setBlock(i + 10, j + 6, k + 9, Blocks.purpleCobble.blockID);
		world.setBlock(i + 10, j + 6, k + 10, Blocks.purpleCobble.blockID);
		world.setBlock(i + 10, j + 6, k + 11, Blocks.purpleCobble.blockID);
		world.setBlock(i + 10, j + 6, k + 12, Blocks.purpleCobble.blockID);
		world.setBlock(i + 10, j + 6, k + 13, Blocks.purpleCobble.blockID);
		world.setBlock(i + 10, j + 6, k + 14, Blocks.purpleCobble.blockID);
		world.setBlock(i + 10, j + 6, k + 15, Blocks.purpleCobble.blockID);
		world.setBlock(i + 10, j + 6, k + 16, Blocks.purpleCobble.blockID);
		
		world.setBlock(i + 11, j + 0, k + 19, Blocks.purpleSand.blockID);
		world.setBlock(i + 11, j + 0, k + 20, Blocks.purpleSand.blockID);
		world.setBlock(i + 11, j + 0, k + 21, Blocks.purpleSand.blockID);
		world.setBlock(i + 11, j + 0, k + 22, Blocks.purpleSand.blockID);
		world.setBlock(i + 11, j + 0, k + 23, Blocks.purpleSand.blockID);
		world.setBlock(i + 11, j + 0, k + 24, Blocks.purpleSand.blockID);
		world.setBlock(i + 12, j + 0, k + 19, Blocks.purpleSand.blockID);
		world.setBlock(i + 12, j + 0, k + 20, Blocks.purpleSand.blockID);
		world.setBlock(i + 12, j + 0, k + 21, Blocks.purpleSand.blockID);
		world.setBlock(i + 12, j + 0, k + 22, Blocks.purpleSand.blockID);
		world.setBlock(i + 12, j + 0, k + 23, Blocks.purpleSand.blockID);
		world.setBlock(i + 12, j + 0, k + 24, Blocks.purpleSand.blockID);
		world.setBlock(i + 13, j + 0, k + 19, Blocks.purpleSand.blockID);
		world.setBlock(i + 13, j + 0, k + 20, Blocks.purpleSand.blockID);
		world.setBlock(i + 13, j + 0, k + 21, Blocks.purpleSand.blockID);
		world.setBlock(i + 13, j + 0, k + 22, Blocks.purpleSand.blockID);
		world.setBlock(i + 13, j + 0, k + 23, Blocks.purpleSand.blockID);
		world.setBlock(i + 13, j + 0, k + 24, Blocks.purpleSand.blockID);
		world.setBlock(i + 14, j + 0, k + 0, Blocks.purpleSand.blockID);
		world.setBlock(i + 14, j + 0, k + 1, Blocks.purpleSand.blockID);
		world.setBlock(i + 14, j + 0, k + 2, Blocks.purpleSand.blockID);
		world.setBlock(i + 14, j + 0, k + 3, Blocks.purpleSand.blockID);
		world.setBlock(i + 14, j + 0, k + 4, Blocks.purpleSand.blockID);
		world.setBlock(i + 14, j + 0, k + 5, Blocks.purpleSand.blockID);
		world.setBlock(i + 14, j + 0, k + 7, Blocks.purpleSand.blockID);
		world.setBlock(i + 14, j + 0, k + 10, Blocks.purpleSand.blockID);
		world.setBlock(i + 14, j + 0, k + 11, Blocks.purpleSand.blockID);
		world.setBlock(i + 14, j + 0, k + 13, Blocks.purpleSand.blockID);
		world.setBlock(i + 14, j + 0, k + 17, Blocks.purpleSand.blockID);
		world.setBlock(i + 14, j + 0, k + 18, Blocks.purpleSand.blockID);
		world.setBlock(i + 14, j + 0, k + 19, Blocks.purpleSand.blockID);
		world.setBlock(i + 14, j + 0, k + 20, Blocks.purpleSand.blockID);
		world.setBlock(i + 14, j + 0, k + 21, Blocks.purpleSand.blockID);
		world.setBlock(i + 14, j + 0, k + 22, Blocks.purpleSand.blockID);
		world.setBlock(i + 14, j + 0, k + 23, Blocks.purpleSand.blockID);
		world.setBlock(i + 14, j + 0, k + 24, Blocks.purpleSand.blockID);
		world.setBlock(i + 15, j + 0, k + 0, Blocks.purpleSand.blockID);
		world.setBlock(i + 15, j + 0, k + 1, Blocks.purpleSand.blockID);
		world.setBlock(i + 15, j + 0, k + 2, Blocks.purpleSand.blockID);
		world.setBlock(i + 15, j + 0, k + 3, Blocks.purpleSand.blockID);
		world.setBlock(i + 15, j + 0, k + 5, Blocks.purpleSand.blockID);
		world.setBlock(i + 15, j + 0, k + 6, Blocks.purpleSand.blockID);
		world.setBlock(i + 15, j + 0, k + 7, Blocks.purpleSand.blockID);
		world.setBlock(i + 15, j + 0, k + 8, Blocks.purpleSand.blockID);
		world.setBlock(i + 15, j + 0, k + 9, Blocks.purpleSand.blockID);
		world.setBlock(i + 15, j + 0, k + 10, Blocks.purpleSand.blockID);
		world.setBlock(i + 15, j + 0, k + 11, Blocks.purpleSand.blockID);
		world.setBlock(i + 15, j + 0, k + 12, Blocks.purpleSand.blockID);
		world.setBlock(i + 15, j + 0, k + 13, Blocks.purpleSand.blockID);
		world.setBlock(i + 15, j + 0, k + 14, Blocks.purpleSand.blockID);
		world.setBlock(i + 15, j + 0, k + 15, Blocks.purpleSand.blockID);
		world.setBlock(i + 15, j + 0, k + 17, Blocks.purpleSand.blockID);
		world.setBlock(i + 15, j + 0, k + 18, Blocks.purpleSand.blockID);
		world.setBlock(i + 15, j + 0, k + 19, Blocks.purpleSand.blockID);
		world.setBlock(i + 15, j + 0, k + 20, Blocks.purpleSand.blockID);
		world.setBlock(i + 15, j + 0, k + 21, Blocks.purpleSand.blockID);
		world.setBlock(i + 15, j + 0, k + 22, Blocks.purpleSand.blockID);
		world.setBlock(i + 15, j + 0, k + 23, Blocks.purpleSand.blockID);
		world.setBlock(i + 15, j + 0, k + 24, Blocks.purpleSand.blockID);
		
		Methods.echo("Success!");
		return true;
	}
}